
Collecting usage statistics. To deactivate, set browser.gatherUsageStats to False.


  You can now view your Streamlit app in your browser.

  Network URL: http://172.31.37.193:8501
  External URL: http://3.37.158.200:8501

2023-08-07 20:33:49.025 Uncaught app exception
Traceback (most recent call last):
  File "/home/ubuntu/.local/lib/python3.9/site-packages/streamlit/runtime/scriptrunner/script_runner.py", line 552, in _run_script
    exec(code, module.__dict__)
  File "/home/ubuntu/test2/pages/Keyword Analysis.py", line 123, in <module>
    st.dataframe(keywords_table, use_container_width=True)
NameError: name 'keywords_table' is not defined
2023-08-07 20:42:28.652 Uncaught app exception
Traceback (most recent call last):
  File "/home/ubuntu/.local/lib/python3.9/site-packages/streamlit/runtime/scriptrunner/script_runner.py", line 552, in _run_script
    exec(code, module.__dict__)
  File "/home/ubuntu/test2/pages/Keyword Analysis.py", line 236, in <module>
    st.table(keywords_table, use_container_width=True)
  File "/home/ubuntu/.local/lib/python3.9/site-packages/streamlit/runtime/metrics_util.py", line 356, in wrapped_func
    result = non_optional_func(*args, **kwargs)
TypeError: table() got an unexpected keyword argument 'use_container_width'
2023-08-07 22:09:00.775 Uncaught app exception
Traceback (most recent call last):
  File "/home/ubuntu/.local/lib/python3.9/site-packages/streamlit/runtime/scriptrunner/script_runner.py", line 552, in _run_script
    exec(code, module.__dict__)
  File "/home/ubuntu/test2/pages/Keyword Analysis.py", line 236, in <module>
    surge_table = surge_table[((surge_table.iloc[:,-1]>5)) & ((surge_table.iloc[:,-1]>surge_table.mean(axis='columns')*2) & (surge_table.iloc[:,-1]>surge_table.iloc[:,-2]))]
  File "/home/ubuntu/.local/lib/python3.9/site-packages/streamlit/runtime/metrics_util.py", line 356, in wrapped_func
    result = non_optional_func(*args, **kwargs)
TypeError: table() got an unexpected keyword argument 'use_container_width'
2023-08-07 22:14:37.191 Uncaught app exception
Traceback (most recent call last):
  File "/home/ubuntu/.local/lib/python3.9/site-packages/streamlit/runtime/scriptrunner/script_runner.py", line 552, in _run_script
    exec(code, module.__dict__)
  File "/home/ubuntu/test2/pages/Keyword Analysis.py", line 237, in <module>
    surge_table = surge_table[((surge_table.iloc[:,1]==NaN)) & ((surge_table.iloc[:,2]==NaN) & (surge_table.iloc[:,-1]>surge_table.iloc[:,-2]))]
NameError: name 'NaN' is not defined

Collecting usage statistics. To deactivate, set browser.gatherUsageStats to False.


  You can now view your Streamlit app in your browser.

  Network URL: http://172.31.37.193:8501
  External URL: http://3.37.158.200:8501

2023-08-07 23:40:51.611 Uncaught app exception
Traceback (most recent call last):
  File "/home/ubuntu/.local/lib/python3.9/site-packages/streamlit/runtime/scriptrunner/script_runner.py", line 552, in _run_script
    exec(code, module.__dict__)
  File "/home/ubuntu/test2/Today.py", line 200, in <module>
    st.text(message)
NameError: name 'message' is not defined
2023-08-08 23:13:58.581 Uncaught app exception
Traceback (most recent call last):
  File "/home/ubuntu/.local/lib/python3.9/site-packages/pandas/core/arrays/datetimelike.py", line 935, in _cmp_method
    other = self._validate_comparison_value(other)
  File "/home/ubuntu/.local/lib/python3.9/site-packages/pandas/core/arrays/datetimelike.py", line 571, in _validate_comparison_value
    raise InvalidComparison(other)
pandas.errors.InvalidComparison: 20230808

During handling of the above exception, another exception occurred:

Traceback (most recent call last):
  File "/home/ubuntu/.local/lib/python3.9/site-packages/streamlit/runtime/scriptrunner/script_runner.py", line 552, in _run_script
    exec(code, module.__dict__)
  File "/home/ubuntu/test2/Today.py", line 132, in <module>
    president_number, president = date_keyword_search("대통령비서실", today, today)
  File "/home/ubuntu/test2/Today.py", line 82, in date_keyword_search
    date_data = data[data['Date'].between(start_date, end_date)]
  File "/home/ubuntu/.local/lib/python3.9/site-packages/pandas/core/series.py", line 5485, in between
    lmask = self >= left
  File "/home/ubuntu/.local/lib/python3.9/site-packages/pandas/core/ops/common.py", line 81, in new_method
    return method(self, other)
  File "/home/ubuntu/.local/lib/python3.9/site-packages/pandas/core/arraylike.py", line 60, in __ge__
    return self._cmp_method(other, operator.ge)
  File "/home/ubuntu/.local/lib/python3.9/site-packages/pandas/core/series.py", line 6096, in _cmp_method
    res_values = ops.comparison_op(lvalues, rvalues, op)
  File "/home/ubuntu/.local/lib/python3.9/site-packages/pandas/core/ops/array_ops.py", line 279, in comparison_op
    res_values = op(lvalues, rvalues)
  File "/home/ubuntu/.local/lib/python3.9/site-packages/pandas/core/ops/common.py", line 81, in new_method
    return method(self, other)
  File "/home/ubuntu/.local/lib/python3.9/site-packages/pandas/core/arraylike.py", line 60, in __ge__
    return self._cmp_method(other, operator.ge)
  File "/home/ubuntu/.local/lib/python3.9/site-packages/pandas/core/arrays/datetimelike.py", line 937, in _cmp_method
    return invalid_comparison(self, other, op)
  File "/home/ubuntu/.local/lib/python3.9/site-packages/pandas/core/ops/invalid.py", line 36, in invalid_comparison
    raise TypeError(f"Invalid comparison between dtype={left.dtype} and {typ}")
TypeError: Invalid comparison between dtype=datetime64[ns] and int
2023-08-08 23:14:44.725 Uncaught app exception
Traceback (most recent call last):
  File "/home/ubuntu/.local/lib/python3.9/site-packages/pandas/core/arrays/datetimelike.py", line 935, in _cmp_method
    other = self._validate_comparison_value(other)
  File "/home/ubuntu/.local/lib/python3.9/site-packages/pandas/core/arrays/datetimelike.py", line 571, in _validate_comparison_value
    raise InvalidComparison(other)
pandas.errors.InvalidComparison: 20230808

During handling of the above exception, another exception occurred:

Traceback (most recent call last):
  File "/home/ubuntu/.local/lib/python3.9/site-packages/streamlit/runtime/scriptrunner/script_runner.py", line 552, in _run_script
    exec(code, module.__dict__)
  File "/home/ubuntu/test2/Today.py", line 132, in <module>
  File "/home/ubuntu/test2/Today.py", line 82, in date_keyword_search
    date_data = data[data['Date'].between(start_date, end_date)]
  File "/home/ubuntu/.local/lib/python3.9/site-packages/pandas/core/series.py", line 5485, in between
    lmask = self >= left
  File "/home/ubuntu/.local/lib/python3.9/site-packages/pandas/core/ops/common.py", line 81, in new_method
    return method(self, other)
  File "/home/ubuntu/.local/lib/python3.9/site-packages/pandas/core/arraylike.py", line 60, in __ge__
    return self._cmp_method(other, operator.ge)
  File "/home/ubuntu/.local/lib/python3.9/site-packages/pandas/core/series.py", line 6096, in _cmp_method
    res_values = ops.comparison_op(lvalues, rvalues, op)
  File "/home/ubuntu/.local/lib/python3.9/site-packages/pandas/core/ops/array_ops.py", line 279, in comparison_op
    res_values = op(lvalues, rvalues)
  File "/home/ubuntu/.local/lib/python3.9/site-packages/pandas/core/ops/common.py", line 81, in new_method
    return method(self, other)
  File "/home/ubuntu/.local/lib/python3.9/site-packages/pandas/core/arraylike.py", line 60, in __ge__
    return self._cmp_method(other, operator.ge)
  File "/home/ubuntu/.local/lib/python3.9/site-packages/pandas/core/arrays/datetimelike.py", line 937, in _cmp_method
    return invalid_comparison(self, other, op)
  File "/home/ubuntu/.local/lib/python3.9/site-packages/pandas/core/ops/invalid.py", line 36, in invalid_comparison
    raise TypeError(f"Invalid comparison between dtype={left.dtype} and {typ}")
TypeError: Invalid comparison between dtype=datetime64[ns] and int
2023-08-08 23:15:27.795 Uncaught app exception
Traceback (most recent call last):
  File "/home/ubuntu/.local/lib/python3.9/site-packages/pandas/core/arrays/datetimelike.py", line 935, in _cmp_method
    other = self._validate_comparison_value(other)
  File "/home/ubuntu/.local/lib/python3.9/site-packages/pandas/core/arrays/datetimelike.py", line 571, in _validate_comparison_value
    raise InvalidComparison(other)
pandas.errors.InvalidComparison: 20230808

During handling of the above exception, another exception occurred:

Traceback (most recent call last):
  File "/home/ubuntu/.local/lib/python3.9/site-packages/streamlit/runtime/scriptrunner/script_runner.py", line 552, in _run_script
    exec(code, module.__dict__)
  File "/home/ubuntu/test2/Today.py", line 132, in <module>
  File "/home/ubuntu/test2/Today.py", line 82, in date_keyword_search
    date_data = data[data['Date'].between(start_date, end_date)]
  File "/home/ubuntu/.local/lib/python3.9/site-packages/pandas/core/series.py", line 5485, in between
    lmask = self >= left
  File "/home/ubuntu/.local/lib/python3.9/site-packages/pandas/core/ops/common.py", line 81, in new_method
    return method(self, other)
  File "/home/ubuntu/.local/lib/python3.9/site-packages/pandas/core/arraylike.py", line 60, in __ge__
    return self._cmp_method(other, operator.ge)
  File "/home/ubuntu/.local/lib/python3.9/site-packages/pandas/core/series.py", line 6096, in _cmp_method
    res_values = ops.comparison_op(lvalues, rvalues, op)
  File "/home/ubuntu/.local/lib/python3.9/site-packages/pandas/core/ops/array_ops.py", line 279, in comparison_op
    res_values = op(lvalues, rvalues)
  File "/home/ubuntu/.local/lib/python3.9/site-packages/pandas/core/ops/common.py", line 81, in new_method
    return method(self, other)
  File "/home/ubuntu/.local/lib/python3.9/site-packages/pandas/core/arraylike.py", line 60, in __ge__
    return self._cmp_method(other, operator.ge)
  File "/home/ubuntu/.local/lib/python3.9/site-packages/pandas/core/arrays/datetimelike.py", line 937, in _cmp_method
    return invalid_comparison(self, other, op)
  File "/home/ubuntu/.local/lib/python3.9/site-packages/pandas/core/ops/invalid.py", line 36, in invalid_comparison
    raise TypeError(f"Invalid comparison between dtype={left.dtype} and {typ}")
TypeError: Invalid comparison between dtype=datetime64[ns] and int
2023-08-08 23:15:40.659 Uncaught app exception
Traceback (most recent call last):
  File "/home/ubuntu/.local/lib/python3.9/site-packages/pandas/core/arrays/datetimelike.py", line 935, in _cmp_method
    other = self._validate_comparison_value(other)
  File "/home/ubuntu/.local/lib/python3.9/site-packages/pandas/core/arrays/datetimelike.py", line 571, in _validate_comparison_value
    raise InvalidComparison(other)
pandas.errors.InvalidComparison: 20230808

During handling of the above exception, another exception occurred:

Traceback (most recent call last):
  File "/home/ubuntu/.local/lib/python3.9/site-packages/streamlit/runtime/scriptrunner/script_runner.py", line 552, in _run_script
    exec(code, module.__dict__)
  File "/home/ubuntu/test2/Today.py", line 132, in <module>
    president_number, president = date_keyword_search("대통령비서실", today, today)
  File "/home/ubuntu/test2/Today.py", line 82, in date_keyword_search
    date_data = data[data['Date'].between(start_date, end_date)]
  File "/home/ubuntu/.local/lib/python3.9/site-packages/pandas/core/series.py", line 5485, in between
    lmask = self >= left
  File "/home/ubuntu/.local/lib/python3.9/site-packages/pandas/core/ops/common.py", line 81, in new_method
    return method(self, other)
  File "/home/ubuntu/.local/lib/python3.9/site-packages/pandas/core/arraylike.py", line 60, in __ge__
    return self._cmp_method(other, operator.ge)
  File "/home/ubuntu/.local/lib/python3.9/site-packages/pandas/core/series.py", line 6096, in _cmp_method
    res_values = ops.comparison_op(lvalues, rvalues, op)
  File "/home/ubuntu/.local/lib/python3.9/site-packages/pandas/core/ops/array_ops.py", line 279, in comparison_op
    res_values = op(lvalues, rvalues)
  File "/home/ubuntu/.local/lib/python3.9/site-packages/pandas/core/ops/common.py", line 81, in new_method
    return method(self, other)
  File "/home/ubuntu/.local/lib/python3.9/site-packages/pandas/core/arraylike.py", line 60, in __ge__
    return self._cmp_method(other, operator.ge)
  File "/home/ubuntu/.local/lib/python3.9/site-packages/pandas/core/arrays/datetimelike.py", line 937, in _cmp_method
    return invalid_comparison(self, other, op)
  File "/home/ubuntu/.local/lib/python3.9/site-packages/pandas/core/ops/invalid.py", line 36, in invalid_comparison
    raise TypeError(f"Invalid comparison between dtype={left.dtype} and {typ}")
TypeError: Invalid comparison between dtype=datetime64[ns] and int
2023-08-08 23:17:49.702 Uncaught app exception
Traceback (most recent call last):
  File "/home/ubuntu/.local/lib/python3.9/site-packages/pandas/core/arrays/datetimelike.py", line 935, in _cmp_method
    other = self._validate_comparison_value(other)
  File "/home/ubuntu/.local/lib/python3.9/site-packages/pandas/core/arrays/datetimelike.py", line 571, in _validate_comparison_value
    raise InvalidComparison(other)
pandas.errors.InvalidComparison: 20230808

During handling of the above exception, another exception occurred:

Traceback (most recent call last):
  File "/home/ubuntu/.local/lib/python3.9/site-packages/streamlit/runtime/scriptrunner/script_runner.py", line 552, in _run_script
    exec(code, module.__dict__)
  File "/home/ubuntu/test2/Today.py", line 132, in <module>
    president_number, president = date_keyword_search("대통령비서실", today, today)
  File "/home/ubuntu/test2/Today.py", line 82, in date_keyword_search
    date_data = data[data['Date'].between(start_date, end_date)]
  File "/home/ubuntu/.local/lib/python3.9/site-packages/pandas/core/series.py", line 5485, in between
    lmask = self >= left
  File "/home/ubuntu/.local/lib/python3.9/site-packages/pandas/core/ops/common.py", line 81, in new_method
    return method(self, other)
  File "/home/ubuntu/.local/lib/python3.9/site-packages/pandas/core/arraylike.py", line 60, in __ge__
    return self._cmp_method(other, operator.ge)
  File "/home/ubuntu/.local/lib/python3.9/site-packages/pandas/core/series.py", line 6096, in _cmp_method
    res_values = ops.comparison_op(lvalues, rvalues, op)
  File "/home/ubuntu/.local/lib/python3.9/site-packages/pandas/core/ops/array_ops.py", line 279, in comparison_op
    res_values = op(lvalues, rvalues)
  File "/home/ubuntu/.local/lib/python3.9/site-packages/pandas/core/ops/common.py", line 81, in new_method
    return method(self, other)
  File "/home/ubuntu/.local/lib/python3.9/site-packages/pandas/core/arraylike.py", line 60, in __ge__
    return self._cmp_method(other, operator.ge)
  File "/home/ubuntu/.local/lib/python3.9/site-packages/pandas/core/arrays/datetimelike.py", line 937, in _cmp_method
    return invalid_comparison(self, other, op)
  File "/home/ubuntu/.local/lib/python3.9/site-packages/pandas/core/ops/invalid.py", line 36, in invalid_comparison
    raise TypeError(f"Invalid comparison between dtype={left.dtype} and {typ}")
TypeError: Invalid comparison between dtype=datetime64[ns] and int
2023-08-08 23:18:05.497 Uncaught app exception
Traceback (most recent call last):
  File "/home/ubuntu/.local/lib/python3.9/site-packages/pandas/core/arrays/datetimelike.py", line 935, in _cmp_method
    other = self._validate_comparison_value(other)
  File "/home/ubuntu/.local/lib/python3.9/site-packages/pandas/core/arrays/datetimelike.py", line 571, in _validate_comparison_value
    raise InvalidComparison(other)
pandas.errors.InvalidComparison: 20230808

During handling of the above exception, another exception occurred:

Traceback (most recent call last):
  File "/home/ubuntu/.local/lib/python3.9/site-packages/streamlit/runtime/scriptrunner/script_runner.py", line 552, in _run_script
    exec(code, module.__dict__)
  File "/home/ubuntu/test2/Today.py", line 132, in <module>
    prime_number, prime = date_keyword_search("총리", today, today)
  File "/home/ubuntu/test2/Today.py", line 82, in date_keyword_search
    date_data = data[data['Date'].between(start_date, end_date)]
  File "/home/ubuntu/.local/lib/python3.9/site-packages/pandas/core/series.py", line 5485, in between
    lmask = self >= left
  File "/home/ubuntu/.local/lib/python3.9/site-packages/pandas/core/ops/common.py", line 81, in new_method
    return method(self, other)
  File "/home/ubuntu/.local/lib/python3.9/site-packages/pandas/core/arraylike.py", line 60, in __ge__
    return self._cmp_method(other, operator.ge)
  File "/home/ubuntu/.local/lib/python3.9/site-packages/pandas/core/series.py", line 6096, in _cmp_method
    res_values = ops.comparison_op(lvalues, rvalues, op)
  File "/home/ubuntu/.local/lib/python3.9/site-packages/pandas/core/ops/array_ops.py", line 279, in comparison_op
    res_values = op(lvalues, rvalues)
  File "/home/ubuntu/.local/lib/python3.9/site-packages/pandas/core/ops/common.py", line 81, in new_method
    return method(self, other)
  File "/home/ubuntu/.local/lib/python3.9/site-packages/pandas/core/arraylike.py", line 60, in __ge__
    return self._cmp_method(other, operator.ge)
  File "/home/ubuntu/.local/lib/python3.9/site-packages/pandas/core/arrays/datetimelike.py", line 937, in _cmp_method
    return invalid_comparison(self, other, op)
  File "/home/ubuntu/.local/lib/python3.9/site-packages/pandas/core/ops/invalid.py", line 36, in invalid_comparison
    raise TypeError(f"Invalid comparison between dtype={left.dtype} and {typ}")
TypeError: Invalid comparison between dtype=datetime64[ns] and int
2023-08-08 23:27:03.091 Uncaught app exception
Traceback (most recent call last):
  File "/home/ubuntu/.local/lib/python3.9/site-packages/pandas/core/arrays/datetimelike.py", line 935, in _cmp_method
    other = self._validate_comparison_value(other)
  File "/home/ubuntu/.local/lib/python3.9/site-packages/pandas/core/arrays/datetimelike.py", line 571, in _validate_comparison_value
    raise InvalidComparison(other)
pandas.errors.InvalidComparison: 20230808

During handling of the above exception, another exception occurred:

Traceback (most recent call last):
  File "/home/ubuntu/.local/lib/python3.9/site-packages/streamlit/runtime/scriptrunner/script_runner.py", line 552, in _run_script
    exec(code, module.__dict__)
  File "/home/ubuntu/test2/Today.py", line 132, in <module>
    prime_number, prime = date_keyword_search("총리", today, today)
  File "/home/ubuntu/test2/Today.py", line 82, in date_keyword_search
    date_data = data[data['Date'].between(start_date, end_date)]
  File "/home/ubuntu/.local/lib/python3.9/site-packages/pandas/core/series.py", line 5485, in between
    lmask = self >= left
  File "/home/ubuntu/.local/lib/python3.9/site-packages/pandas/core/ops/common.py", line 81, in new_method
    return method(self, other)
  File "/home/ubuntu/.local/lib/python3.9/site-packages/pandas/core/arraylike.py", line 60, in __ge__
    return self._cmp_method(other, operator.ge)
  File "/home/ubuntu/.local/lib/python3.9/site-packages/pandas/core/series.py", line 6096, in _cmp_method
    res_values = ops.comparison_op(lvalues, rvalues, op)
  File "/home/ubuntu/.local/lib/python3.9/site-packages/pandas/core/ops/array_ops.py", line 279, in comparison_op
    res_values = op(lvalues, rvalues)
  File "/home/ubuntu/.local/lib/python3.9/site-packages/pandas/core/ops/common.py", line 81, in new_method
    return method(self, other)
  File "/home/ubuntu/.local/lib/python3.9/site-packages/pandas/core/arraylike.py", line 60, in __ge__
    return self._cmp_method(other, operator.ge)
  File "/home/ubuntu/.local/lib/python3.9/site-packages/pandas/core/arrays/datetimelike.py", line 937, in _cmp_method
    return invalid_comparison(self, other, op)
  File "/home/ubuntu/.local/lib/python3.9/site-packages/pandas/core/ops/invalid.py", line 36, in invalid_comparison
    raise TypeError(f"Invalid comparison between dtype={left.dtype} and {typ}")
TypeError: Invalid comparison between dtype=datetime64[ns] and int
2023-08-08 23:28:38.082 Uncaught app exception
Traceback (most recent call last):
  File "/home/ubuntu/.local/lib/python3.9/site-packages/pandas/core/arrays/datetimelike.py", line 935, in _cmp_method
    other = self._validate_comparison_value(other)
  File "/home/ubuntu/.local/lib/python3.9/site-packages/pandas/core/arrays/datetimelike.py", line 571, in _validate_comparison_value
    raise InvalidComparison(other)
pandas.errors.InvalidComparison: 20230808

During handling of the above exception, another exception occurred:

Traceback (most recent call last):
  File "/home/ubuntu/.local/lib/python3.9/site-packages/streamlit/runtime/scriptrunner/script_runner.py", line 552, in _run_script
    exec(code, module.__dict__)
  File "/home/ubuntu/test2/Today.py", line 132, in <module>
    president_number, president = date_keyword_search("대통령비서실", today, today)
  File "/home/ubuntu/test2/Today.py", line 82, in date_keyword_search
    date_data = data[data['Date'].between(start_date, end_date)]
  File "/home/ubuntu/.local/lib/python3.9/site-packages/pandas/core/series.py", line 5485, in between
    lmask = self >= left
  File "/home/ubuntu/.local/lib/python3.9/site-packages/pandas/core/ops/common.py", line 81, in new_method
    return method(self, other)
  File "/home/ubuntu/.local/lib/python3.9/site-packages/pandas/core/arraylike.py", line 60, in __ge__
    return self._cmp_method(other, operator.ge)
  File "/home/ubuntu/.local/lib/python3.9/site-packages/pandas/core/series.py", line 6096, in _cmp_method
    res_values = ops.comparison_op(lvalues, rvalues, op)
  File "/home/ubuntu/.local/lib/python3.9/site-packages/pandas/core/ops/array_ops.py", line 279, in comparison_op
    res_values = op(lvalues, rvalues)
  File "/home/ubuntu/.local/lib/python3.9/site-packages/pandas/core/ops/common.py", line 81, in new_method
    return method(self, other)
  File "/home/ubuntu/.local/lib/python3.9/site-packages/pandas/core/arraylike.py", line 60, in __ge__
    return self._cmp_method(other, operator.ge)
  File "/home/ubuntu/.local/lib/python3.9/site-packages/pandas/core/arrays/datetimelike.py", line 937, in _cmp_method
    return invalid_comparison(self, other, op)
  File "/home/ubuntu/.local/lib/python3.9/site-packages/pandas/core/ops/invalid.py", line 36, in invalid_comparison
    raise TypeError(f"Invalid comparison between dtype={left.dtype} and {typ}")
TypeError: Invalid comparison between dtype=datetime64[ns] and int
2023-08-08 23:30:41.870 Uncaught app exception
Traceback (most recent call last):
  File "/home/ubuntu/.local/lib/python3.9/site-packages/pandas/core/arrays/datetimelike.py", line 935, in _cmp_method
    other = self._validate_comparison_value(other)
  File "/home/ubuntu/.local/lib/python3.9/site-packages/pandas/core/arrays/datetimelike.py", line 571, in _validate_comparison_value
    raise InvalidComparison(other)
pandas.errors.InvalidComparison: 20230808

During handling of the above exception, another exception occurred:

Traceback (most recent call last):
  File "/home/ubuntu/.local/lib/python3.9/site-packages/streamlit/runtime/scriptrunner/script_runner.py", line 552, in _run_script
    exec(code, module.__dict__)
  File "/home/ubuntu/test2/Today.py", line 132, in <module>
    president_number, president = date_keyword_search("대통령비서실", today, today)
  File "/home/ubuntu/test2/Today.py", line 82, in date_keyword_search
    date_data = data[data['Date'].between(start_date, end_date)]
  File "/home/ubuntu/.local/lib/python3.9/site-packages/pandas/core/series.py", line 5485, in between
    lmask = self >= left
  File "/home/ubuntu/.local/lib/python3.9/site-packages/pandas/core/ops/common.py", line 81, in new_method
    return method(self, other)
  File "/home/ubuntu/.local/lib/python3.9/site-packages/pandas/core/arraylike.py", line 60, in __ge__
    return self._cmp_method(other, operator.ge)
  File "/home/ubuntu/.local/lib/python3.9/site-packages/pandas/core/series.py", line 6096, in _cmp_method
    res_values = ops.comparison_op(lvalues, rvalues, op)
  File "/home/ubuntu/.local/lib/python3.9/site-packages/pandas/core/ops/array_ops.py", line 279, in comparison_op
    res_values = op(lvalues, rvalues)
  File "/home/ubuntu/.local/lib/python3.9/site-packages/pandas/core/ops/common.py", line 81, in new_method
    return method(self, other)
  File "/home/ubuntu/.local/lib/python3.9/site-packages/pandas/core/arraylike.py", line 60, in __ge__
    return self._cmp_method(other, operator.ge)
  File "/home/ubuntu/.local/lib/python3.9/site-packages/pandas/core/arrays/datetimelike.py", line 937, in _cmp_method
    return invalid_comparison(self, other, op)
  File "/home/ubuntu/.local/lib/python3.9/site-packages/pandas/core/ops/invalid.py", line 36, in invalid_comparison
    raise TypeError(f"Invalid comparison between dtype={left.dtype} and {typ}")
TypeError: Invalid comparison between dtype=datetime64[ns] and int
2023-08-08 23:31:13.701 Uncaught app exception
Traceback (most recent call last):
  File "/home/ubuntu/.local/lib/python3.9/site-packages/pandas/core/arrays/datetimelike.py", line 935, in _cmp_method
    other = self._validate_comparison_value(other)
  File "/home/ubuntu/.local/lib/python3.9/site-packages/pandas/core/arrays/datetimelike.py", line 571, in _validate_comparison_value
    raise InvalidComparison(other)
pandas.errors.InvalidComparison: 20230808

During handling of the above exception, another exception occurred:

Traceback (most recent call last):
  File "/home/ubuntu/.local/lib/python3.9/site-packages/streamlit/runtime/scriptrunner/script_runner.py", line 552, in _run_script
    exec(code, module.__dict__)
  File "/home/ubuntu/test2/Today.py", line 132, in <module>
    president_number, president = date_keyword_search("대통령비서실", today, today)
  File "/home/ubuntu/test2/Today.py", line 82, in date_keyword_search
    date_data = data[data['Date'].between(start_date, end_date)]
  File "/home/ubuntu/.local/lib/python3.9/site-packages/pandas/core/series.py", line 5485, in between
    lmask = self >= left
  File "/home/ubuntu/.local/lib/python3.9/site-packages/pandas/core/ops/common.py", line 81, in new_method
    return method(self, other)
  File "/home/ubuntu/.local/lib/python3.9/site-packages/pandas/core/arraylike.py", line 60, in __ge__
    return self._cmp_method(other, operator.ge)
  File "/home/ubuntu/.local/lib/python3.9/site-packages/pandas/core/series.py", line 6096, in _cmp_method
    res_values = ops.comparison_op(lvalues, rvalues, op)
  File "/home/ubuntu/.local/lib/python3.9/site-packages/pandas/core/ops/array_ops.py", line 279, in comparison_op
    res_values = op(lvalues, rvalues)
  File "/home/ubuntu/.local/lib/python3.9/site-packages/pandas/core/ops/common.py", line 81, in new_method
    return method(self, other)
  File "/home/ubuntu/.local/lib/python3.9/site-packages/pandas/core/arraylike.py", line 60, in __ge__
    return self._cmp_method(other, operator.ge)
  File "/home/ubuntu/.local/lib/python3.9/site-packages/pandas/core/arrays/datetimelike.py", line 937, in _cmp_method
    return invalid_comparison(self, other, op)
  File "/home/ubuntu/.local/lib/python3.9/site-packages/pandas/core/ops/invalid.py", line 36, in invalid_comparison
    raise TypeError(f"Invalid comparison between dtype={left.dtype} and {typ}")
TypeError: Invalid comparison between dtype=datetime64[ns] and int
2023-08-08 23:31:20.053 Uncaught app exception
Traceback (most recent call last):
  File "/home/ubuntu/.local/lib/python3.9/site-packages/pandas/core/arrays/datetimelike.py", line 935, in _cmp_method
    other = self._validate_comparison_value(other)
  File "/home/ubuntu/.local/lib/python3.9/site-packages/pandas/core/arrays/datetimelike.py", line 571, in _validate_comparison_value
    raise InvalidComparison(other)
pandas.errors.InvalidComparison: 20230808

During handling of the above exception, another exception occurred:

Traceback (most recent call last):
  File "/home/ubuntu/.local/lib/python3.9/site-packages/streamlit/runtime/scriptrunner/script_runner.py", line 552, in _run_script
    exec(code, module.__dict__)
  File "/home/ubuntu/test2/Today.py", line 132, in <module>
    president_number, president = date_keyword_search("대통령비서실", today, today)
  File "/home/ubuntu/test2/Today.py", line 82, in date_keyword_search
    date_data = data[data['Date'].between(start_date, end_date)]
  File "/home/ubuntu/.local/lib/python3.9/site-packages/pandas/core/series.py", line 5485, in between
    lmask = self >= left
  File "/home/ubuntu/.local/lib/python3.9/site-packages/pandas/core/ops/common.py", line 81, in new_method
    return method(self, other)
  File "/home/ubuntu/.local/lib/python3.9/site-packages/pandas/core/arraylike.py", line 60, in __ge__
    return self._cmp_method(other, operator.ge)
  File "/home/ubuntu/.local/lib/python3.9/site-packages/pandas/core/series.py", line 6096, in _cmp_method
    res_values = ops.comparison_op(lvalues, rvalues, op)
  File "/home/ubuntu/.local/lib/python3.9/site-packages/pandas/core/ops/array_ops.py", line 279, in comparison_op
    res_values = op(lvalues, rvalues)
  File "/home/ubuntu/.local/lib/python3.9/site-packages/pandas/core/ops/common.py", line 81, in new_method
    return method(self, other)
  File "/home/ubuntu/.local/lib/python3.9/site-packages/pandas/core/arraylike.py", line 60, in __ge__
    return self._cmp_method(other, operator.ge)
  File "/home/ubuntu/.local/lib/python3.9/site-packages/pandas/core/arrays/datetimelike.py", line 937, in _cmp_method
    return invalid_comparison(self, other, op)
  File "/home/ubuntu/.local/lib/python3.9/site-packages/pandas/core/ops/invalid.py", line 36, in invalid_comparison
    raise TypeError(f"Invalid comparison between dtype={left.dtype} and {typ}")
TypeError: Invalid comparison between dtype=datetime64[ns] and int
2023-08-08 23:32:06.570 Uncaught app exception
Traceback (most recent call last):
  File "/home/ubuntu/.local/lib/python3.9/site-packages/pandas/core/arrays/datetimelike.py", line 935, in _cmp_method
    other = self._validate_comparison_value(other)
  File "/home/ubuntu/.local/lib/python3.9/site-packages/pandas/core/arrays/datetimelike.py", line 571, in _validate_comparison_value
    raise InvalidComparison(other)
pandas.errors.InvalidComparison: 20230808

During handling of the above exception, another exception occurred:

Traceback (most recent call last):
  File "/home/ubuntu/.local/lib/python3.9/site-packages/streamlit/runtime/scriptrunner/script_runner.py", line 552, in _run_script
    exec(code, module.__dict__)
  File "/home/ubuntu/test2/Today.py", line 132, in <module>
    president_number, president = date_keyword_search("대통령비서실", today, today)
  File "/home/ubuntu/test2/Today.py", line 82, in date_keyword_search
    date_data = data[data['Date'].between(start_date, end_date)]
  File "/home/ubuntu/.local/lib/python3.9/site-packages/pandas/core/series.py", line 5485, in between
    lmask = self >= left
  File "/home/ubuntu/.local/lib/python3.9/site-packages/pandas/core/ops/common.py", line 81, in new_method
    return method(self, other)
  File "/home/ubuntu/.local/lib/python3.9/site-packages/pandas/core/arraylike.py", line 60, in __ge__
    return self._cmp_method(other, operator.ge)
  File "/home/ubuntu/.local/lib/python3.9/site-packages/pandas/core/series.py", line 6096, in _cmp_method
    res_values = ops.comparison_op(lvalues, rvalues, op)
  File "/home/ubuntu/.local/lib/python3.9/site-packages/pandas/core/ops/array_ops.py", line 279, in comparison_op
    res_values = op(lvalues, rvalues)
  File "/home/ubuntu/.local/lib/python3.9/site-packages/pandas/core/ops/common.py", line 81, in new_method
    return method(self, other)
  File "/home/ubuntu/.local/lib/python3.9/site-packages/pandas/core/arraylike.py", line 60, in __ge__
    return self._cmp_method(other, operator.ge)
  File "/home/ubuntu/.local/lib/python3.9/site-packages/pandas/core/arrays/datetimelike.py", line 937, in _cmp_method
    return invalid_comparison(self, other, op)
  File "/home/ubuntu/.local/lib/python3.9/site-packages/pandas/core/ops/invalid.py", line 36, in invalid_comparison
    raise TypeError(f"Invalid comparison between dtype={left.dtype} and {typ}")
TypeError: Invalid comparison between dtype=datetime64[ns] and int
2023-08-08 23:32:14.610 Uncaught app exception
Traceback (most recent call last):
  File "/home/ubuntu/.local/lib/python3.9/site-packages/pandas/core/arrays/datetimelike.py", line 935, in _cmp_method
    other = self._validate_comparison_value(other)
  File "/home/ubuntu/.local/lib/python3.9/site-packages/pandas/core/arrays/datetimelike.py", line 571, in _validate_comparison_value
    raise InvalidComparison(other)
pandas.errors.InvalidComparison: 20230808

During handling of the above exception, another exception occurred:

Traceback (most recent call last):
  File "/home/ubuntu/.local/lib/python3.9/site-packages/streamlit/runtime/scriptrunner/script_runner.py", line 552, in _run_script
    exec(code, module.__dict__)
  File "/home/ubuntu/test2/Today.py", line 132, in <module>
    president_number, president = date_keyword_search("대통령비서실", today, today)
  File "/home/ubuntu/test2/Today.py", line 82, in date_keyword_search
    date_data = data[data['Date'].between(start_date, end_date)]
  File "/home/ubuntu/.local/lib/python3.9/site-packages/pandas/core/series.py", line 5485, in between
    lmask = self >= left
  File "/home/ubuntu/.local/lib/python3.9/site-packages/pandas/core/ops/common.py", line 81, in new_method
    return method(self, other)
  File "/home/ubuntu/.local/lib/python3.9/site-packages/pandas/core/arraylike.py", line 60, in __ge__
    return self._cmp_method(other, operator.ge)
  File "/home/ubuntu/.local/lib/python3.9/site-packages/pandas/core/series.py", line 6096, in _cmp_method
    res_values = ops.comparison_op(lvalues, rvalues, op)
  File "/home/ubuntu/.local/lib/python3.9/site-packages/pandas/core/ops/array_ops.py", line 279, in comparison_op
    res_values = op(lvalues, rvalues)
  File "/home/ubuntu/.local/lib/python3.9/site-packages/pandas/core/ops/common.py", line 81, in new_method
    return method(self, other)
  File "/home/ubuntu/.local/lib/python3.9/site-packages/pandas/core/arraylike.py", line 60, in __ge__
    return self._cmp_method(other, operator.ge)
  File "/home/ubuntu/.local/lib/python3.9/site-packages/pandas/core/arrays/datetimelike.py", line 937, in _cmp_method
    return invalid_comparison(self, other, op)
  File "/home/ubuntu/.local/lib/python3.9/site-packages/pandas/core/ops/invalid.py", line 36, in invalid_comparison
    raise TypeError(f"Invalid comparison between dtype={left.dtype} and {typ}")
TypeError: Invalid comparison between dtype=datetime64[ns] and int
2023-08-08 23:37:51.267 Uncaught app exception
Traceback (most recent call last):
  File "/home/ubuntu/.local/lib/python3.9/site-packages/streamlit/runtime/scriptrunner/script_runner.py", line 552, in _run_script
    exec(code, module.__dict__)
  File "/home/ubuntu/test2/Today.py", line 126, in <module>
    today = re.sub('-', '', today)
  File "/usr/lib/python3.9/re.py", line 210, in sub
    return _compile(pattern, flags).sub(repl, string, count)
TypeError: expected string or bytes-like object
2023-08-08 23:38:37.340 Uncaught app exception
Traceback (most recent call last):
  File "/home/ubuntu/.local/lib/python3.9/site-packages/streamlit/runtime/scriptrunner/script_runner.py", line 552, in _run_script
    exec(code, module.__dict__)
  File "/home/ubuntu/test2/Today.py", line 127, in <module>
    today = re.sub('-', '', today)
  File "/usr/lib/python3.9/re.py", line 210, in sub
    return _compile(pattern, flags).sub(repl, string, count)
TypeError: expected string or bytes-like object
2023-08-08 23:38:50.766 Uncaught app exception
Traceback (most recent call last):
  File "/home/ubuntu/.local/lib/python3.9/site-packages/streamlit/runtime/scriptrunner/script_runner.py", line 552, in _run_script
    exec(code, module.__dict__)
  File "/home/ubuntu/test2/Today.py", line 204, in <module>
    st.text(message)
NameError: name 'message' is not defined
2023-08-08 23:39:12.035 Uncaught app exception
Traceback (most recent call last):
  File "/home/ubuntu/.local/lib/python3.9/site-packages/streamlit/runtime/scriptrunner/script_runner.py", line 552, in _run_script
    exec(code, module.__dict__)
  File "/home/ubuntu/test2/Today.py", line 205, in <module>
    st.text(message)
NameError: name 'message' is not defined
2023-08-08 23:39:32.643 Uncaught app exception
Traceback (most recent call last):
  File "/home/ubuntu/.local/lib/python3.9/site-packages/streamlit/runtime/scriptrunner/script_runner.py", line 552, in _run_script
    exec(code, module.__dict__)
  File "/home/ubuntu/test2/Today.py", line 205, in <module>
    st.text(message)
NameError: name 'message' is not defined
2023-08-08 23:40:56.533 Uncaught app exception
Traceback (most recent call last):
  File "/home/ubuntu/.local/lib/python3.9/site-packages/streamlit/runtime/scriptrunner/script_runner.py", line 552, in _run_script
    exec(code, module.__dict__)
  File "/home/ubuntu/test2/Today.py", line 205, in <module>
    st.subheader(f"{today} 주요 보도")
NameError: name 'message' is not defined
2023-08-08 23:41:35.239 Uncaught app exception
Traceback (most recent call last):
  File "/home/ubuntu/.local/lib/python3.9/site-packages/streamlit/runtime/scriptrunner/script_runner.py", line 552, in _run_script
    exec(code, module.__dict__)
  File "/home/ubuntu/test2/Today.py", line 205, in <module>
    with st.container():
NameError: name 'message' is not defined
2023-08-08 23:42:13.005 Uncaught app exception
Traceback (most recent call last):
  File "/home/ubuntu/.local/lib/python3.9/site-packages/streamlit/runtime/scriptrunner/script_runner.py", line 552, in _run_script
    exec(code, module.__dict__)
  File "/home/ubuntu/test2/Today.py", line 205, in <module>
    with st.container():
NameError: name 'message' is not defined
2023-08-08 23:42:38.386 Uncaught app exception
Traceback (most recent call last):
  File "/home/ubuntu/.local/lib/python3.9/site-packages/streamlit/runtime/scriptrunner/script_runner.py", line 552, in _run_script
    exec(code, module.__dict__)
  File "/home/ubuntu/test2/Today.py", line 205, in <module>
    with st.container():
NameError: name 'message' is not defined
2023-08-08 23:42:44.035 Uncaught app exception
Traceback (most recent call last):
  File "/home/ubuntu/.local/lib/python3.9/site-packages/streamlit/runtime/scriptrunner/script_runner.py", line 552, in _run_script
    exec(code, module.__dict__)
  File "/home/ubuntu/test2/Today.py", line 205, in <module>
    with st.container():
NameError: name 'message' is not defined
2023-08-08 23:42:52.533 Uncaught app exception
Traceback (most recent call last):
  File "/home/ubuntu/.local/lib/python3.9/site-packages/streamlit/runtime/scriptrunner/script_runner.py", line 552, in _run_script
    exec(code, module.__dict__)
  File "/home/ubuntu/test2/Today.py", line 205, in <module>
    with st.container():
NameError: name 'message' is not defined
2023-08-08 23:43:58.150 Uncaught app exception
Traceback (most recent call last):
  File "/home/ubuntu/.local/lib/python3.9/site-packages/streamlit/runtime/scriptrunner/script_runner.py", line 552, in _run_script
    exec(code, module.__dict__)
  File "/home/ubuntu/test2/Today.py", line 205, in <module>
    with st.container():
NameError: name 'message' is not defined
2023-08-08 23:44:02.705 Uncaught app exception
Traceback (most recent call last):
  File "/home/ubuntu/.local/lib/python3.9/site-packages/streamlit/runtime/scriptrunner/script_runner.py", line 552, in _run_script
    exec(code, module.__dict__)
  File "/home/ubuntu/test2/Today.py", line 205, in <module>
    with st.container():
NameError: name 'message' is not defined
2023-08-08 23:44:05.854 Uncaught app exception
Traceback (most recent call last):
  File "/home/ubuntu/.local/lib/python3.9/site-packages/streamlit/runtime/scriptrunner/script_runner.py", line 552, in _run_script
    exec(code, module.__dict__)
  File "/home/ubuntu/test2/Today.py", line 205, in <module>
    with st.container():
NameError: name 'message' is not defined
2023-08-08 23:44:27.022 Uncaught app exception
Traceback (most recent call last):
  File "/home/ubuntu/.local/lib/python3.9/site-packages/streamlit/runtime/scriptrunner/script_runner.py", line 552, in _run_script
    exec(code, module.__dict__)
  File "/home/ubuntu/test2/Today.py", line 205, in <module>
    with st.container():
NameError: name 'message' is not defined
2023-08-08
2023-08-08
2023-08-08
2023-08-08 00:00:00
2023-08-08
2023-08-08 00:00:00
2023-08-08
2023-08-08 00:00:00
2023-08-08
2023-08-08 00:00:00
2023-08-08
2023-08-08 00:00:00
2023-08-08
2023-08-08 00:00:00
2023-08-08
2023-08-08 00:00:00
2023-08-08
2023-08-08 00:00:00
2023-08-08
2023-08-08 00:00:00
2023-08-08
2023-08-08 00:00:00
2023-08-08
2023-08-08 00:00:00
2023-08-08
2023-08-08 00:00:00
  Stopping...

Collecting usage statistics. To deactivate, set browser.gatherUsageStats to False.


  You can now view your Streamlit app in your browser.

  Network URL: http://172.31.37.193:8501
  External URL: http://3.37.158.200:8501

using cached model. /home/ubuntu/test2/.cache/kobert_v1.zip
using cached model. /home/ubuntu/test2/.cache/kobert_news_wiki_ko_cased-1087f8699e.spiece
using cached model. /home/ubuntu/test2/.cache/kobert_news_wiki_ko_cased-1087f8699e.spiece
using cached model. /home/ubuntu/test2/.cache/kobert_v1.zip
using cached model. /home/ubuntu/test2/.cache/kobert_news_wiki_ko_cased-1087f8699e.spiece
using cached model. /home/ubuntu/test2/.cache/kobert_news_wiki_ko_cased-1087f8699e.spiece
  Stopping...

Collecting usage statistics. To deactivate, set browser.gatherUsageStats to False.


  You can now view your Streamlit app in your browser.

  Network URL: http://172.31.37.193:8501
  External URL: http://3.37.158.200:8501

2023-08-09 12:43:44.416 Uncaught app exception
Traceback (most recent call last):
  File "/home/ubuntu/.local/lib/python3.9/site-packages/streamlit/runtime/scriptrunner/script_runner.py", line 552, in _run_script
    exec(code, module.__dict__)
  File "/home/ubuntu/test2/pages/Keyword Analysis.py", line 225, in <module>
    wc.generate_from_frequencies(top_related_words)
  File "/home/ubuntu/.local/lib/python3.9/site-packages/wordcloud/wordcloud.py", line 410, in generate_from_frequencies
    raise ValueError("We need at least 1 word to plot a word cloud, "
ValueError: We need at least 1 word to plot a word cloud, got 0.
2023-08-09 12:45:08.934 Uncaught app exception
Traceback (most recent call last):
  File "/home/ubuntu/.local/lib/python3.9/site-packages/streamlit/runtime/scriptrunner/script_runner.py", line 552, in _run_script
    exec(code, module.__dict__)
  File "/home/ubuntu/test2/pages/Keyword Analysis.py", line 173, in <module>
    date_top_related_words.iloc[d,0] = f'{date_top_related_words.iloc[d,0]}  :  {date_top_related_words.iloc[d,1]}건'
  File "/home/ubuntu/.local/lib/python3.9/site-packages/pandas/core/indexing.py", line 1096, in __getitem__
    return self.obj._get_value(*key, takeable=self._takeable)
  File "/home/ubuntu/.local/lib/python3.9/site-packages/pandas/core/frame.py", line 3868, in _get_value
    return series._values[index]
IndexError: index 5 is out of bounds for axis 0 with size 5
2023-08-09 12:45:47.875 Uncaught app exception
Traceback (most recent call last):
  File "/home/ubuntu/.local/lib/python3.9/site-packages/streamlit/runtime/scriptrunner/script_runner.py", line 552, in _run_script
    exec(code, module.__dict__)
  File "/home/ubuntu/test2/pages/Keyword Analysis.py", line 173, in <module>
    date_top_related_words.iloc[d,0] = f'{date_top_related_words.iloc[d,0]}  :  {date_top_related_words.iloc[d,1]}건'
  File "/home/ubuntu/.local/lib/python3.9/site-packages/pandas/core/indexing.py", line 1096, in __getitem__
    return self.obj._get_value(*key, takeable=self._takeable)
  File "/home/ubuntu/.local/lib/python3.9/site-packages/pandas/core/frame.py", line 3868, in _get_value
    return series._values[index]
IndexError: index 12 is out of bounds for axis 0 with size 12
2023-08-09 12:46:01.392 Uncaught app exception
Traceback (most recent call last):
  File "/home/ubuntu/.local/lib/python3.9/site-packages/streamlit/runtime/scriptrunner/script_runner.py", line 552, in _run_script
    exec(code, module.__dict__)
  File "/home/ubuntu/test2/pages/Keyword Analysis.py", line 173, in <module>
    date_top_related_words.iloc[d,0] = f'{date_top_related_words.iloc[d,0]}  :  {date_top_related_words.iloc[d,1]}건'
  File "/home/ubuntu/.local/lib/python3.9/site-packages/pandas/core/indexing.py", line 1096, in __getitem__
    return self.obj._get_value(*key, takeable=self._takeable)
  File "/home/ubuntu/.local/lib/python3.9/site-packages/pandas/core/frame.py", line 3868, in _get_value
    return series._values[index]
IndexError: index 5 is out of bounds for axis 0 with size 5
2023-08-09 12:46:42.105 Uncaught app exception
Traceback (most recent call last):
  File "/home/ubuntu/.local/lib/python3.9/site-packages/transformers/modeling_utils.py", line 1211, in from_pretrained
    state_dict = torch.load(resolved_archive_file, map_location="cpu")
  File "/home/ubuntu/.local/lib/python3.9/site-packages/torch/serialization.py", line 608, in load
    return _legacy_load(opened_file, map_location, pickle_module, **pickle_load_args)
  File "/home/ubuntu/.local/lib/python3.9/site-packages/torch/serialization.py", line 794, in _legacy_load
    deserialized_objects[key]._set_from_file(f, offset, f_should_read_directly)
RuntimeError: unexpected EOF, expected 8 more bytes. The file might be corrupted.

During handling of the above exception, another exception occurred:

Traceback (most recent call last):
  File "/home/ubuntu/.local/lib/python3.9/site-packages/streamlit/runtime/scriptrunner/script_runner.py", line 552, in _run_script
    exec(code, module.__dict__)
  File "/home/ubuntu/test2/pages/Keyword Analysis.py", line 276, in <module>
    bertmodel, vocab = get_pytorch_kobert_model()
  File "/home/ubuntu/.local/lib/python3.9/site-packages/kobert/pytorch_kobert.py", line 52, in get_pytorch_kobert_model
    return get_kobert_model(model_path, vocab_path, ctx)
  File "/home/ubuntu/.local/lib/python3.9/site-packages/kobert/pytorch_kobert.py", line 27, in get_kobert_model
    bertmodel = BertModel.from_pretrained(model_path, return_dict=False)
  File "/home/ubuntu/.local/lib/python3.9/site-packages/transformers/modeling_utils.py", line 1213, in from_pretrained
    raise OSError(
OSError: Unable to load weights from pytorch checkpoint file for '.cache/kobert_from_pretrained' at '.cache/kobert_from_pretrained/pytorch_model.bin'If you tried to load a PyTorch model from a TF 2.0 checkpoint, please set from_tf=True. 
2023-08-10 08:50:53.024 Uncaught app exception
Traceback (most recent call last):
  File "/home/ubuntu/.local/lib/python3.9/site-packages/streamlit/runtime/scriptrunner/script_runner.py", line 552, in _run_script
    exec(code, module.__dict__)
  File "/home/ubuntu/test2/pages/Keyword Analysis.py", line 225, in <module>
    wc.generate_from_frequencies(top_related_words)
  File "/home/ubuntu/.local/lib/python3.9/site-packages/wordcloud/wordcloud.py", line 410, in generate_from_frequencies
    raise ValueError("We need at least 1 word to plot a word cloud, "
ValueError: We need at least 1 word to plot a word cloud, got 0.
using cached model. /home/ubuntu/test2/.cache/kobert_v1.zip
using cached model. /home/ubuntu/test2/.cache/kobert_news_wiki_ko_cased-1087f8699e.spiece
using cached model. /home/ubuntu/test2/.cache/kobert_news_wiki_ko_cased-1087f8699e.spiece
using cached model. /home/ubuntu/test2/.cache/kobert_v1.zip
using cached model. /home/ubuntu/test2/.cache/kobert_news_wiki_ko_cased-1087f8699e.spiece
using cached model. /home/ubuntu/test2/.cache/kobert_news_wiki_ko_cased-1087f8699e.spiece
using cached model. /home/ubuntu/test2/.cache/kobert_v1.zip
using cached model. /home/ubuntu/test2/.cache/kobert_news_wiki_ko_cased-1087f8699e.spiece
using cached model. /home/ubuntu/test2/.cache/kobert_v1.zip
using cached model. /home/ubuntu/test2/.cache/kobert_news_wiki_ko_cased-1087f8699e.spiece
using cached model. /home/ubuntu/test2/.cache/kobert_news_wiki_ko_cased-1087f8699e.spiece
using cached model. /home/ubuntu/test2/.cache/kobert_v1.zip
using cached model. /home/ubuntu/test2/.cache/kobert_news_wiki_ko_cased-1087f8699e.spiece
using cached model. /home/ubuntu/test2/.cache/kobert_news_wiki_ko_cased-1087f8699e.spiece
  Stopping...

Collecting usage statistics. To deactivate, set browser.gatherUsageStats to False.


  You can now view your Streamlit app in your browser.

  Network URL: http://172.31.37.193:8501
  External URL: http://3.37.158.200:8501

2023-08-11 10:58:52.937 Uncaught app exception
Traceback (most recent call last):
  File "/home/ubuntu/.local/lib/python3.9/site-packages/streamlit/runtime/scriptrunner/script_runner.py", line 552, in _run_script
    exec(code, module.__dict__)
  File "/home/ubuntu/test2/Today.py", line 201, in <module>
    if len(noun) > 1 and noun not in stop_words and noun != search_word:
NameError: name 'search_word' is not defined

Collecting usage statistics. To deactivate, set browser.gatherUsageStats to False.


  You can now view your Streamlit app in your browser.

  Network URL: http://172.31.37.193:8508
  External URL: http://3.37.158.200:8508


Collecting usage statistics. To deactivate, set browser.gatherUsageStats to False.


  You can now view your Streamlit app in your browser.

  Network URL: http://172.31.37.193:8501
  External URL: http://3.37.158.200:8501

  Stopping...

Collecting usage statistics. To deactivate, set browser.gatherUsageStats to False.


  You can now view your Streamlit app in your browser.

  Network URL: http://172.31.37.193:8501
  External URL: http://3.37.158.200:8501

  Stopping...

Collecting usage statistics. To deactivate, set browser.gatherUsageStats to False.


  You can now view your Streamlit app in your browser.

  Network URL: http://172.31.37.193:8502
  External URL: http://3.37.158.200:8502

  Stopping...

Collecting usage statistics. To deactivate, set browser.gatherUsageStats to False.


  You can now view your Streamlit app in your browser.

  Network URL: http://172.31.37.193:8502
  External URL: http://3.37.158.200:8502


  A new version of Streamlit is available.

  See what's new at https://discuss.streamlit.io/c/announcements

  Enter the following command to upgrade:
  $ pip install streamlit --upgrade

  Stopping...
Traceback (most recent call last):
  File "/home/ubuntu/.local/bin/streamlit", line 5, in <module>
    from streamlit.web.cli import main
  File "/home/ubuntu/.local/lib/python3.9/site-packages/streamlit/__init__.py", line 55, in <module>
    from streamlit.delta_generator import DeltaGenerator as _DeltaGenerator
  File "/home/ubuntu/.local/lib/python3.9/site-packages/streamlit/delta_generator.py", line 36, in <module>
    from streamlit import config, cursor, env_util, logger, runtime, type_util, util
  File "/home/ubuntu/.local/lib/python3.9/site-packages/streamlit/cursor.py", line 18, in <module>
    from streamlit.runtime.scriptrunner import get_script_run_ctx
  File "/home/ubuntu/.local/lib/python3.9/site-packages/streamlit/runtime/__init__.py", line 16, in <module>
    from streamlit.runtime.runtime import Runtime as Runtime
  File "/home/ubuntu/.local/lib/python3.9/site-packages/streamlit/runtime/runtime.py", line 31, in <module>
    from streamlit.runtime.app_session import AppSession
  File "/home/ubuntu/.local/lib/python3.9/site-packages/streamlit/runtime/app_session.py", line 35, in <module>
    from streamlit.runtime import caching, legacy_caching
  File "/home/ubuntu/.local/lib/python3.9/site-packages/streamlit/runtime/caching/__init__.py", line 21, in <module>
    from streamlit.runtime.caching.cache_data_api import (
  File "/home/ubuntu/.local/lib/python3.9/site-packages/streamlit/runtime/caching/cache_data_api.py", line 32, in <module>
    from streamlit.runtime.caching.cache_errors import CacheError, CacheKeyNotFoundError
  File "/home/ubuntu/.local/lib/python3.9/site-packages/streamlit/runtime/caching/cache_errors.py", line 18, in <module>
    from streamlit import type_util
  File "/home/ubuntu/.local/lib/python3.9/site-packages/streamlit/type_util.py", line 42, in <module>
    from pandas import DataFrame, Index, MultiIndex, Series
  File "/home/ubuntu/.local/lib/python3.9/site-packages/pandas/__init__.py", line 48, in <module>
    from pandas.core.api import (
  File "/home/ubuntu/.local/lib/python3.9/site-packages/pandas/core/api.py", line 47, in <module>
    from pandas.core.groupby import (
  File "/home/ubuntu/.local/lib/python3.9/site-packages/pandas/core/groupby/__init__.py", line 1, in <module>
    from pandas.core.groupby.generic import (
  File "/home/ubuntu/.local/lib/python3.9/site-packages/pandas/core/groupby/generic.py", line 30, in <module>
    from pandas._libs import (
  File "<frozen importlib._bootstrap>", line 398, in parent
KeyboardInterrupt

Collecting usage statistics. To deactivate, set browser.gatherUsageStats to False.


  You can now view your Streamlit app in your browser.

  Network URL: http://172.31.37.193:8501
  External URL: http://3.37.158.200:8501

2023-10-21 13:38:11.675 Uncaught app exception
Traceback (most recent call last):
  File "/home/ubuntu/.local/lib/python3.9/site-packages/streamlit/runtime/caching/storage/in_memory_cache_storage_wrapper.py", line 87, in get
    entry_bytes = self._read_from_mem_cache(key)
  File "/home/ubuntu/.local/lib/python3.9/site-packages/streamlit/runtime/caching/storage/in_memory_cache_storage_wrapper.py", line 137, in _read_from_mem_cache
    raise CacheStorageKeyNotFoundError("Key not found in mem cache")
streamlit.runtime.caching.storage.cache_storage_protocol.CacheStorageKeyNotFoundError: Key not found in mem cache

During handling of the above exception, another exception occurred:

Traceback (most recent call last):
  File "/home/ubuntu/.local/lib/python3.9/site-packages/streamlit/runtime/caching/cache_data_api.py", line 634, in read_result
    pickled_entry = self.storage.get(key)
  File "/home/ubuntu/.local/lib/python3.9/site-packages/streamlit/runtime/caching/storage/in_memory_cache_storage_wrapper.py", line 89, in get
    entry_bytes = self._persist_storage.get(key)
  File "/home/ubuntu/.local/lib/python3.9/site-packages/streamlit/runtime/caching/storage/local_disk_cache_storage.py", line 155, in get
    raise CacheStorageKeyNotFoundError(
streamlit.runtime.caching.storage.cache_storage_protocol.CacheStorageKeyNotFoundError: Local disk cache storage is disabled (persist=None)

The above exception was the direct cause of the following exception:

Traceback (most recent call last):
  File "/home/ubuntu/.local/lib/python3.9/site-packages/streamlit/runtime/caching/cache_utils.py", line 263, in _get_or_create_cached_value
    cached_result = cache.read_result(value_key)
  File "/home/ubuntu/.local/lib/python3.9/site-packages/streamlit/runtime/caching/cache_data_api.py", line 636, in read_result
    raise CacheKeyNotFoundError(str(e)) from e
streamlit.runtime.caching.cache_errors.CacheKeyNotFoundError: Local disk cache storage is disabled (persist=None)

During handling of the above exception, another exception occurred:

Traceback (most recent call last):
  File "/home/ubuntu/.local/lib/python3.9/site-packages/streamlit/runtime/caching/storage/in_memory_cache_storage_wrapper.py", line 87, in get
    entry_bytes = self._read_from_mem_cache(key)
  File "/home/ubuntu/.local/lib/python3.9/site-packages/streamlit/runtime/caching/storage/in_memory_cache_storage_wrapper.py", line 137, in _read_from_mem_cache
    raise CacheStorageKeyNotFoundError("Key not found in mem cache")
streamlit.runtime.caching.storage.cache_storage_protocol.CacheStorageKeyNotFoundError: Key not found in mem cache

During handling of the above exception, another exception occurred:

Traceback (most recent call last):
  File "/home/ubuntu/.local/lib/python3.9/site-packages/streamlit/runtime/caching/cache_data_api.py", line 634, in read_result
    pickled_entry = self.storage.get(key)
  File "/home/ubuntu/.local/lib/python3.9/site-packages/streamlit/runtime/caching/storage/in_memory_cache_storage_wrapper.py", line 89, in get
    entry_bytes = self._persist_storage.get(key)
  File "/home/ubuntu/.local/lib/python3.9/site-packages/streamlit/runtime/caching/storage/local_disk_cache_storage.py", line 155, in get
    raise CacheStorageKeyNotFoundError(
streamlit.runtime.caching.storage.cache_storage_protocol.CacheStorageKeyNotFoundError: Local disk cache storage is disabled (persist=None)

The above exception was the direct cause of the following exception:

Traceback (most recent call last):
  File "/home/ubuntu/.local/lib/python3.9/site-packages/streamlit/runtime/caching/cache_utils.py", line 311, in _handle_cache_miss
    cached_result = cache.read_result(value_key)
  File "/home/ubuntu/.local/lib/python3.9/site-packages/streamlit/runtime/caching/cache_data_api.py", line 636, in read_result
    raise CacheKeyNotFoundError(str(e)) from e
streamlit.runtime.caching.cache_errors.CacheKeyNotFoundError: Local disk cache storage is disabled (persist=None)

During handling of the above exception, another exception occurred:

Traceback (most recent call last):
  File "/home/ubuntu/.local/lib/python3.9/site-packages/streamlit/runtime/scriptrunner/script_runner.py", line 552, in _run_script
    exec(code, module.__dict__)
  File "/home/ubuntu/test2/pages/Keyword Analysis.py", line 58, in <module>
    data = load_data()
  File "/home/ubuntu/.local/lib/python3.9/site-packages/streamlit/runtime/caching/cache_utils.py", line 211, in wrapper
    return cached_func(*args, **kwargs)
  File "/home/ubuntu/.local/lib/python3.9/site-packages/streamlit/runtime/caching/cache_utils.py", line 240, in __call__
    return self._get_or_create_cached_value(args, kwargs)
  File "/home/ubuntu/.local/lib/python3.9/site-packages/streamlit/runtime/caching/cache_utils.py", line 266, in _get_or_create_cached_value
    return self._handle_cache_miss(cache, value_key, func_args, func_kwargs)
  File "/home/ubuntu/.local/lib/python3.9/site-packages/streamlit/runtime/caching/cache_utils.py", line 320, in _handle_cache_miss
    computed_value = self._info.func(*func_args, **func_kwargs)
  File "/home/ubuntu/test2/pages/Keyword Analysis.py", line 52, in load_data
    data = pd.read_csv(file_path)
  File "/home/ubuntu/.local/lib/python3.9/site-packages/pandas/io/parsers/readers.py", line 912, in read_csv
    return _read(filepath_or_buffer, kwds)
  File "/home/ubuntu/.local/lib/python3.9/site-packages/pandas/io/parsers/readers.py", line 577, in _read
    parser = TextFileReader(filepath_or_buffer, **kwds)
  File "/home/ubuntu/.local/lib/python3.9/site-packages/pandas/io/parsers/readers.py", line 1407, in __init__
    self._engine = self._make_engine(f, self.engine)
  File "/home/ubuntu/.local/lib/python3.9/site-packages/pandas/io/parsers/readers.py", line 1661, in _make_engine
    self.handles = get_handle(
  File "/home/ubuntu/.local/lib/python3.9/site-packages/pandas/io/common.py", line 859, in get_handle
    handle = open(
FileNotFoundError: [Errno 2] No such file or directory: 'test2/full_result.csv'

Collecting usage statistics. To deactivate, set browser.gatherUsageStats to False.


  You can now view your Streamlit app in your browser.

  Network URL: http://172.31.37.193:8502
  External URL: http://3.37.158.200:8502


  A new version of Streamlit is available.

  See what's new at https://discuss.streamlit.io/c/announcements

  Enter the following command to upgrade:
  $ pip install streamlit --upgrade

2023-10-21 13:39:32.085 Uncaught app exception
Traceback (most recent call last):
  File "/home/ubuntu/.local/lib/python3.9/site-packages/streamlit/runtime/caching/storage/in_memory_cache_storage_wrapper.py", line 87, in get
    entry_bytes = self._read_from_mem_cache(key)
  File "/home/ubuntu/.local/lib/python3.9/site-packages/streamlit/runtime/caching/storage/in_memory_cache_storage_wrapper.py", line 137, in _read_from_mem_cache
    raise CacheStorageKeyNotFoundError("Key not found in mem cache")
streamlit.runtime.caching.storage.cache_storage_protocol.CacheStorageKeyNotFoundError: Key not found in mem cache

During handling of the above exception, another exception occurred:

Traceback (most recent call last):
  File "/home/ubuntu/.local/lib/python3.9/site-packages/streamlit/runtime/caching/cache_data_api.py", line 634, in read_result
    pickled_entry = self.storage.get(key)
  File "/home/ubuntu/.local/lib/python3.9/site-packages/streamlit/runtime/caching/storage/in_memory_cache_storage_wrapper.py", line 89, in get
    entry_bytes = self._persist_storage.get(key)
  File "/home/ubuntu/.local/lib/python3.9/site-packages/streamlit/runtime/caching/storage/local_disk_cache_storage.py", line 155, in get
    raise CacheStorageKeyNotFoundError(
streamlit.runtime.caching.storage.cache_storage_protocol.CacheStorageKeyNotFoundError: Local disk cache storage is disabled (persist=None)

The above exception was the direct cause of the following exception:

Traceback (most recent call last):
  File "/home/ubuntu/.local/lib/python3.9/site-packages/streamlit/runtime/caching/cache_utils.py", line 263, in _get_or_create_cached_value
    cached_result = cache.read_result(value_key)
  File "/home/ubuntu/.local/lib/python3.9/site-packages/streamlit/runtime/caching/cache_data_api.py", line 636, in read_result
    raise CacheKeyNotFoundError(str(e)) from e
streamlit.runtime.caching.cache_errors.CacheKeyNotFoundError: Local disk cache storage is disabled (persist=None)

During handling of the above exception, another exception occurred:

Traceback (most recent call last):
  File "/home/ubuntu/.local/lib/python3.9/site-packages/streamlit/runtime/caching/storage/in_memory_cache_storage_wrapper.py", line 87, in get
    entry_bytes = self._read_from_mem_cache(key)
  File "/home/ubuntu/.local/lib/python3.9/site-packages/streamlit/runtime/caching/storage/in_memory_cache_storage_wrapper.py", line 137, in _read_from_mem_cache
    raise CacheStorageKeyNotFoundError("Key not found in mem cache")
streamlit.runtime.caching.storage.cache_storage_protocol.CacheStorageKeyNotFoundError: Key not found in mem cache

During handling of the above exception, another exception occurred:

Traceback (most recent call last):
  File "/home/ubuntu/.local/lib/python3.9/site-packages/streamlit/runtime/caching/cache_data_api.py", line 634, in read_result
    pickled_entry = self.storage.get(key)
  File "/home/ubuntu/.local/lib/python3.9/site-packages/streamlit/runtime/caching/storage/in_memory_cache_storage_wrapper.py", line 89, in get
    entry_bytes = self._persist_storage.get(key)
  File "/home/ubuntu/.local/lib/python3.9/site-packages/streamlit/runtime/caching/storage/local_disk_cache_storage.py", line 155, in get
    raise CacheStorageKeyNotFoundError(
streamlit.runtime.caching.storage.cache_storage_protocol.CacheStorageKeyNotFoundError: Local disk cache storage is disabled (persist=None)

The above exception was the direct cause of the following exception:

Traceback (most recent call last):
  File "/home/ubuntu/.local/lib/python3.9/site-packages/streamlit/runtime/caching/cache_utils.py", line 311, in _handle_cache_miss
    cached_result = cache.read_result(value_key)
  File "/home/ubuntu/.local/lib/python3.9/site-packages/streamlit/runtime/caching/cache_data_api.py", line 636, in read_result
    raise CacheKeyNotFoundError(str(e)) from e
streamlit.runtime.caching.cache_errors.CacheKeyNotFoundError: Local disk cache storage is disabled (persist=None)

During handling of the above exception, another exception occurred:

Traceback (most recent call last):
  File "/home/ubuntu/.local/lib/python3.9/site-packages/streamlit/runtime/scriptrunner/script_runner.py", line 552, in _run_script
    exec(code, module.__dict__)
  File "/home/ubuntu/test2/pages/Keyword Analysis.py", line 58, in <module>
    data = load_data()
  File "/home/ubuntu/.local/lib/python3.9/site-packages/streamlit/runtime/caching/cache_utils.py", line 211, in wrapper
    return cached_func(*args, **kwargs)
  File "/home/ubuntu/.local/lib/python3.9/site-packages/streamlit/runtime/caching/cache_utils.py", line 240, in __call__
    return self._get_or_create_cached_value(args, kwargs)
  File "/home/ubuntu/.local/lib/python3.9/site-packages/streamlit/runtime/caching/cache_utils.py", line 266, in _get_or_create_cached_value
    return self._handle_cache_miss(cache, value_key, func_args, func_kwargs)
  File "/home/ubuntu/.local/lib/python3.9/site-packages/streamlit/runtime/caching/cache_utils.py", line 320, in _handle_cache_miss
    computed_value = self._info.func(*func_args, **func_kwargs)
  File "/home/ubuntu/test2/pages/Keyword Analysis.py", line 52, in load_data
    data = pd.read_csv(file_path)
  File "/home/ubuntu/.local/lib/python3.9/site-packages/pandas/io/parsers/readers.py", line 912, in read_csv
    return _read(filepath_or_buffer, kwds)
  File "/home/ubuntu/.local/lib/python3.9/site-packages/pandas/io/parsers/readers.py", line 577, in _read
    parser = TextFileReader(filepath_or_buffer, **kwds)
  File "/home/ubuntu/.local/lib/python3.9/site-packages/pandas/io/parsers/readers.py", line 1407, in __init__
    self._engine = self._make_engine(f, self.engine)
  File "/home/ubuntu/.local/lib/python3.9/site-packages/pandas/io/parsers/readers.py", line 1661, in _make_engine
    self.handles = get_handle(
  File "/home/ubuntu/.local/lib/python3.9/site-packages/pandas/io/common.py", line 859, in get_handle
    handle = open(
FileNotFoundError: [Errno 2] No such file or directory: 'test2/full_result.csv'
  Stopping...
