
Collecting usage statistics. To deactivate, set browser.gatherUsageStats to False.


  You can now view your Streamlit app in your browser.

  Network URL: http://172.31.37.193:8501
  External URL: http://3.37.158.200:8501

2023-08-07 20:33:49.025 Uncaught app exception
Traceback (most recent call last):
  File "/home/ubuntu/.local/lib/python3.9/site-packages/streamlit/runtime/scriptrunner/script_runner.py", line 552, in _run_script
    exec(code, module.__dict__)
  File "/home/ubuntu/test2/pages/Keyword Analysis.py", line 123, in <module>
    st.dataframe(keywords_table, use_container_width=True)
NameError: name 'keywords_table' is not defined
2023-08-07 20:42:28.652 Uncaught app exception
Traceback (most recent call last):
  File "/home/ubuntu/.local/lib/python3.9/site-packages/streamlit/runtime/scriptrunner/script_runner.py", line 552, in _run_script
    exec(code, module.__dict__)
  File "/home/ubuntu/test2/pages/Keyword Analysis.py", line 236, in <module>
    st.table(keywords_table, use_container_width=True)
  File "/home/ubuntu/.local/lib/python3.9/site-packages/streamlit/runtime/metrics_util.py", line 356, in wrapped_func
    result = non_optional_func(*args, **kwargs)
TypeError: table() got an unexpected keyword argument 'use_container_width'
2023-08-07 22:09:00.775 Uncaught app exception
Traceback (most recent call last):
  File "/home/ubuntu/.local/lib/python3.9/site-packages/streamlit/runtime/scriptrunner/script_runner.py", line 552, in _run_script
    exec(code, module.__dict__)
  File "/home/ubuntu/test2/pages/Keyword Analysis.py", line 236, in <module>
    surge_table = surge_table[((surge_table.iloc[:,-1]>5)) & ((surge_table.iloc[:,-1]>surge_table.mean(axis='columns')*2) & (surge_table.iloc[:,-1]>surge_table.iloc[:,-2]))]
  File "/home/ubuntu/.local/lib/python3.9/site-packages/streamlit/runtime/metrics_util.py", line 356, in wrapped_func
    result = non_optional_func(*args, **kwargs)
TypeError: table() got an unexpected keyword argument 'use_container_width'
2023-08-07 22:14:37.191 Uncaught app exception
Traceback (most recent call last):
  File "/home/ubuntu/.local/lib/python3.9/site-packages/streamlit/runtime/scriptrunner/script_runner.py", line 552, in _run_script
    exec(code, module.__dict__)
  File "/home/ubuntu/test2/pages/Keyword Analysis.py", line 237, in <module>
    surge_table = surge_table[((surge_table.iloc[:,1]==NaN)) & ((surge_table.iloc[:,2]==NaN) & (surge_table.iloc[:,-1]>surge_table.iloc[:,-2]))]
NameError: name 'NaN' is not defined

Collecting usage statistics. To deactivate, set browser.gatherUsageStats to False.


  You can now view your Streamlit app in your browser.

  Network URL: http://172.31.37.193:8501
  External URL: http://3.37.158.200:8501

2023-08-07 23:40:51.611 Uncaught app exception
Traceback (most recent call last):
  File "/home/ubuntu/.local/lib/python3.9/site-packages/streamlit/runtime/scriptrunner/script_runner.py", line 552, in _run_script
    exec(code, module.__dict__)
  File "/home/ubuntu/test2/Today.py", line 200, in <module>
    st.text(message)
NameError: name 'message' is not defined
2023-08-08 23:13:58.581 Uncaught app exception
Traceback (most recent call last):
  File "/home/ubuntu/.local/lib/python3.9/site-packages/pandas/core/arrays/datetimelike.py", line 935, in _cmp_method
    other = self._validate_comparison_value(other)
  File "/home/ubuntu/.local/lib/python3.9/site-packages/pandas/core/arrays/datetimelike.py", line 571, in _validate_comparison_value
    raise InvalidComparison(other)
pandas.errors.InvalidComparison: 20230808

During handling of the above exception, another exception occurred:

Traceback (most recent call last):
  File "/home/ubuntu/.local/lib/python3.9/site-packages/streamlit/runtime/scriptrunner/script_runner.py", line 552, in _run_script
    exec(code, module.__dict__)
  File "/home/ubuntu/test2/Today.py", line 132, in <module>
    president_number, president = date_keyword_search("대통령비서실", today, today)
  File "/home/ubuntu/test2/Today.py", line 82, in date_keyword_search
    date_data = data[data['Date'].between(start_date, end_date)]
  File "/home/ubuntu/.local/lib/python3.9/site-packages/pandas/core/series.py", line 5485, in between
    lmask = self >= left
  File "/home/ubuntu/.local/lib/python3.9/site-packages/pandas/core/ops/common.py", line 81, in new_method
    return method(self, other)
  File "/home/ubuntu/.local/lib/python3.9/site-packages/pandas/core/arraylike.py", line 60, in __ge__
    return self._cmp_method(other, operator.ge)
  File "/home/ubuntu/.local/lib/python3.9/site-packages/pandas/core/series.py", line 6096, in _cmp_method
    res_values = ops.comparison_op(lvalues, rvalues, op)
  File "/home/ubuntu/.local/lib/python3.9/site-packages/pandas/core/ops/array_ops.py", line 279, in comparison_op
    res_values = op(lvalues, rvalues)
  File "/home/ubuntu/.local/lib/python3.9/site-packages/pandas/core/ops/common.py", line 81, in new_method
    return method(self, other)
  File "/home/ubuntu/.local/lib/python3.9/site-packages/pandas/core/arraylike.py", line 60, in __ge__
    return self._cmp_method(other, operator.ge)
  File "/home/ubuntu/.local/lib/python3.9/site-packages/pandas/core/arrays/datetimelike.py", line 937, in _cmp_method
    return invalid_comparison(self, other, op)
  File "/home/ubuntu/.local/lib/python3.9/site-packages/pandas/core/ops/invalid.py", line 36, in invalid_comparison
    raise TypeError(f"Invalid comparison between dtype={left.dtype} and {typ}")
TypeError: Invalid comparison between dtype=datetime64[ns] and int
2023-08-08 23:14:44.725 Uncaught app exception
Traceback (most recent call last):
  File "/home/ubuntu/.local/lib/python3.9/site-packages/pandas/core/arrays/datetimelike.py", line 935, in _cmp_method
    other = self._validate_comparison_value(other)
  File "/home/ubuntu/.local/lib/python3.9/site-packages/pandas/core/arrays/datetimelike.py", line 571, in _validate_comparison_value
    raise InvalidComparison(other)
pandas.errors.InvalidComparison: 20230808

During handling of the above exception, another exception occurred:

Traceback (most recent call last):
  File "/home/ubuntu/.local/lib/python3.9/site-packages/streamlit/runtime/scriptrunner/script_runner.py", line 552, in _run_script
    exec(code, module.__dict__)
  File "/home/ubuntu/test2/Today.py", line 132, in <module>
  File "/home/ubuntu/test2/Today.py", line 82, in date_keyword_search
    date_data = data[data['Date'].between(start_date, end_date)]
  File "/home/ubuntu/.local/lib/python3.9/site-packages/pandas/core/series.py", line 5485, in between
    lmask = self >= left
  File "/home/ubuntu/.local/lib/python3.9/site-packages/pandas/core/ops/common.py", line 81, in new_method
    return method(self, other)
  File "/home/ubuntu/.local/lib/python3.9/site-packages/pandas/core/arraylike.py", line 60, in __ge__
    return self._cmp_method(other, operator.ge)
  File "/home/ubuntu/.local/lib/python3.9/site-packages/pandas/core/series.py", line 6096, in _cmp_method
    res_values = ops.comparison_op(lvalues, rvalues, op)
  File "/home/ubuntu/.local/lib/python3.9/site-packages/pandas/core/ops/array_ops.py", line 279, in comparison_op
    res_values = op(lvalues, rvalues)
  File "/home/ubuntu/.local/lib/python3.9/site-packages/pandas/core/ops/common.py", line 81, in new_method
    return method(self, other)
  File "/home/ubuntu/.local/lib/python3.9/site-packages/pandas/core/arraylike.py", line 60, in __ge__
    return self._cmp_method(other, operator.ge)
  File "/home/ubuntu/.local/lib/python3.9/site-packages/pandas/core/arrays/datetimelike.py", line 937, in _cmp_method
    return invalid_comparison(self, other, op)
  File "/home/ubuntu/.local/lib/python3.9/site-packages/pandas/core/ops/invalid.py", line 36, in invalid_comparison
    raise TypeError(f"Invalid comparison between dtype={left.dtype} and {typ}")
TypeError: Invalid comparison between dtype=datetime64[ns] and int
2023-08-08 23:15:27.795 Uncaught app exception
Traceback (most recent call last):
  File "/home/ubuntu/.local/lib/python3.9/site-packages/pandas/core/arrays/datetimelike.py", line 935, in _cmp_method
    other = self._validate_comparison_value(other)
  File "/home/ubuntu/.local/lib/python3.9/site-packages/pandas/core/arrays/datetimelike.py", line 571, in _validate_comparison_value
    raise InvalidComparison(other)
pandas.errors.InvalidComparison: 20230808

During handling of the above exception, another exception occurred:

Traceback (most recent call last):
  File "/home/ubuntu/.local/lib/python3.9/site-packages/streamlit/runtime/scriptrunner/script_runner.py", line 552, in _run_script
    exec(code, module.__dict__)
  File "/home/ubuntu/test2/Today.py", line 132, in <module>
  File "/home/ubuntu/test2/Today.py", line 82, in date_keyword_search
    date_data = data[data['Date'].between(start_date, end_date)]
  File "/home/ubuntu/.local/lib/python3.9/site-packages/pandas/core/series.py", line 5485, in between
    lmask = self >= left
  File "/home/ubuntu/.local/lib/python3.9/site-packages/pandas/core/ops/common.py", line 81, in new_method
    return method(self, other)
  File "/home/ubuntu/.local/lib/python3.9/site-packages/pandas/core/arraylike.py", line 60, in __ge__
    return self._cmp_method(other, operator.ge)
  File "/home/ubuntu/.local/lib/python3.9/site-packages/pandas/core/series.py", line 6096, in _cmp_method
    res_values = ops.comparison_op(lvalues, rvalues, op)
  File "/home/ubuntu/.local/lib/python3.9/site-packages/pandas/core/ops/array_ops.py", line 279, in comparison_op
    res_values = op(lvalues, rvalues)
  File "/home/ubuntu/.local/lib/python3.9/site-packages/pandas/core/ops/common.py", line 81, in new_method
    return method(self, other)
  File "/home/ubuntu/.local/lib/python3.9/site-packages/pandas/core/arraylike.py", line 60, in __ge__
    return self._cmp_method(other, operator.ge)
  File "/home/ubuntu/.local/lib/python3.9/site-packages/pandas/core/arrays/datetimelike.py", line 937, in _cmp_method
    return invalid_comparison(self, other, op)
  File "/home/ubuntu/.local/lib/python3.9/site-packages/pandas/core/ops/invalid.py", line 36, in invalid_comparison
    raise TypeError(f"Invalid comparison between dtype={left.dtype} and {typ}")
TypeError: Invalid comparison between dtype=datetime64[ns] and int
2023-08-08 23:15:40.659 Uncaught app exception
Traceback (most recent call last):
  File "/home/ubuntu/.local/lib/python3.9/site-packages/pandas/core/arrays/datetimelike.py", line 935, in _cmp_method
    other = self._validate_comparison_value(other)
  File "/home/ubuntu/.local/lib/python3.9/site-packages/pandas/core/arrays/datetimelike.py", line 571, in _validate_comparison_value
    raise InvalidComparison(other)
pandas.errors.InvalidComparison: 20230808

During handling of the above exception, another exception occurred:

Traceback (most recent call last):
  File "/home/ubuntu/.local/lib/python3.9/site-packages/streamlit/runtime/scriptrunner/script_runner.py", line 552, in _run_script
    exec(code, module.__dict__)
  File "/home/ubuntu/test2/Today.py", line 132, in <module>
    president_number, president = date_keyword_search("대통령비서실", today, today)
  File "/home/ubuntu/test2/Today.py", line 82, in date_keyword_search
    date_data = data[data['Date'].between(start_date, end_date)]
  File "/home/ubuntu/.local/lib/python3.9/site-packages/pandas/core/series.py", line 5485, in between
    lmask = self >= left
  File "/home/ubuntu/.local/lib/python3.9/site-packages/pandas/core/ops/common.py", line 81, in new_method
    return method(self, other)
  File "/home/ubuntu/.local/lib/python3.9/site-packages/pandas/core/arraylike.py", line 60, in __ge__
    return self._cmp_method(other, operator.ge)
  File "/home/ubuntu/.local/lib/python3.9/site-packages/pandas/core/series.py", line 6096, in _cmp_method
    res_values = ops.comparison_op(lvalues, rvalues, op)
  File "/home/ubuntu/.local/lib/python3.9/site-packages/pandas/core/ops/array_ops.py", line 279, in comparison_op
    res_values = op(lvalues, rvalues)
  File "/home/ubuntu/.local/lib/python3.9/site-packages/pandas/core/ops/common.py", line 81, in new_method
    return method(self, other)
  File "/home/ubuntu/.local/lib/python3.9/site-packages/pandas/core/arraylike.py", line 60, in __ge__
    return self._cmp_method(other, operator.ge)
  File "/home/ubuntu/.local/lib/python3.9/site-packages/pandas/core/arrays/datetimelike.py", line 937, in _cmp_method
    return invalid_comparison(self, other, op)
  File "/home/ubuntu/.local/lib/python3.9/site-packages/pandas/core/ops/invalid.py", line 36, in invalid_comparison
    raise TypeError(f"Invalid comparison between dtype={left.dtype} and {typ}")
TypeError: Invalid comparison between dtype=datetime64[ns] and int
2023-08-08 23:17:49.702 Uncaught app exception
Traceback (most recent call last):
  File "/home/ubuntu/.local/lib/python3.9/site-packages/pandas/core/arrays/datetimelike.py", line 935, in _cmp_method
    other = self._validate_comparison_value(other)
  File "/home/ubuntu/.local/lib/python3.9/site-packages/pandas/core/arrays/datetimelike.py", line 571, in _validate_comparison_value
    raise InvalidComparison(other)
pandas.errors.InvalidComparison: 20230808

During handling of the above exception, another exception occurred:

Traceback (most recent call last):
  File "/home/ubuntu/.local/lib/python3.9/site-packages/streamlit/runtime/scriptrunner/script_runner.py", line 552, in _run_script
    exec(code, module.__dict__)
  File "/home/ubuntu/test2/Today.py", line 132, in <module>
    president_number, president = date_keyword_search("대통령비서실", today, today)
  File "/home/ubuntu/test2/Today.py", line 82, in date_keyword_search
    date_data = data[data['Date'].between(start_date, end_date)]
  File "/home/ubuntu/.local/lib/python3.9/site-packages/pandas/core/series.py", line 5485, in between
    lmask = self >= left
  File "/home/ubuntu/.local/lib/python3.9/site-packages/pandas/core/ops/common.py", line 81, in new_method
    return method(self, other)
  File "/home/ubuntu/.local/lib/python3.9/site-packages/pandas/core/arraylike.py", line 60, in __ge__
    return self._cmp_method(other, operator.ge)
  File "/home/ubuntu/.local/lib/python3.9/site-packages/pandas/core/series.py", line 6096, in _cmp_method
    res_values = ops.comparison_op(lvalues, rvalues, op)
  File "/home/ubuntu/.local/lib/python3.9/site-packages/pandas/core/ops/array_ops.py", line 279, in comparison_op
    res_values = op(lvalues, rvalues)
  File "/home/ubuntu/.local/lib/python3.9/site-packages/pandas/core/ops/common.py", line 81, in new_method
    return method(self, other)
  File "/home/ubuntu/.local/lib/python3.9/site-packages/pandas/core/arraylike.py", line 60, in __ge__
    return self._cmp_method(other, operator.ge)
  File "/home/ubuntu/.local/lib/python3.9/site-packages/pandas/core/arrays/datetimelike.py", line 937, in _cmp_method
    return invalid_comparison(self, other, op)
  File "/home/ubuntu/.local/lib/python3.9/site-packages/pandas/core/ops/invalid.py", line 36, in invalid_comparison
    raise TypeError(f"Invalid comparison between dtype={left.dtype} and {typ}")
TypeError: Invalid comparison between dtype=datetime64[ns] and int
2023-08-08 23:18:05.497 Uncaught app exception
Traceback (most recent call last):
  File "/home/ubuntu/.local/lib/python3.9/site-packages/pandas/core/arrays/datetimelike.py", line 935, in _cmp_method
    other = self._validate_comparison_value(other)
  File "/home/ubuntu/.local/lib/python3.9/site-packages/pandas/core/arrays/datetimelike.py", line 571, in _validate_comparison_value
    raise InvalidComparison(other)
pandas.errors.InvalidComparison: 20230808

During handling of the above exception, another exception occurred:

Traceback (most recent call last):
  File "/home/ubuntu/.local/lib/python3.9/site-packages/streamlit/runtime/scriptrunner/script_runner.py", line 552, in _run_script
    exec(code, module.__dict__)
  File "/home/ubuntu/test2/Today.py", line 132, in <module>
    prime_number, prime = date_keyword_search("총리", today, today)
  File "/home/ubuntu/test2/Today.py", line 82, in date_keyword_search
    date_data = data[data['Date'].between(start_date, end_date)]
  File "/home/ubuntu/.local/lib/python3.9/site-packages/pandas/core/series.py", line 5485, in between
    lmask = self >= left
  File "/home/ubuntu/.local/lib/python3.9/site-packages/pandas/core/ops/common.py", line 81, in new_method
    return method(self, other)
  File "/home/ubuntu/.local/lib/python3.9/site-packages/pandas/core/arraylike.py", line 60, in __ge__
    return self._cmp_method(other, operator.ge)
  File "/home/ubuntu/.local/lib/python3.9/site-packages/pandas/core/series.py", line 6096, in _cmp_method
    res_values = ops.comparison_op(lvalues, rvalues, op)
  File "/home/ubuntu/.local/lib/python3.9/site-packages/pandas/core/ops/array_ops.py", line 279, in comparison_op
    res_values = op(lvalues, rvalues)
  File "/home/ubuntu/.local/lib/python3.9/site-packages/pandas/core/ops/common.py", line 81, in new_method
    return method(self, other)
  File "/home/ubuntu/.local/lib/python3.9/site-packages/pandas/core/arraylike.py", line 60, in __ge__
    return self._cmp_method(other, operator.ge)
  File "/home/ubuntu/.local/lib/python3.9/site-packages/pandas/core/arrays/datetimelike.py", line 937, in _cmp_method
    return invalid_comparison(self, other, op)
  File "/home/ubuntu/.local/lib/python3.9/site-packages/pandas/core/ops/invalid.py", line 36, in invalid_comparison
    raise TypeError(f"Invalid comparison between dtype={left.dtype} and {typ}")
TypeError: Invalid comparison between dtype=datetime64[ns] and int
2023-08-08 23:27:03.091 Uncaught app exception
Traceback (most recent call last):
  File "/home/ubuntu/.local/lib/python3.9/site-packages/pandas/core/arrays/datetimelike.py", line 935, in _cmp_method
    other = self._validate_comparison_value(other)
  File "/home/ubuntu/.local/lib/python3.9/site-packages/pandas/core/arrays/datetimelike.py", line 571, in _validate_comparison_value
    raise InvalidComparison(other)
pandas.errors.InvalidComparison: 20230808

During handling of the above exception, another exception occurred:

Traceback (most recent call last):
  File "/home/ubuntu/.local/lib/python3.9/site-packages/streamlit/runtime/scriptrunner/script_runner.py", line 552, in _run_script
    exec(code, module.__dict__)
  File "/home/ubuntu/test2/Today.py", line 132, in <module>
    prime_number, prime = date_keyword_search("총리", today, today)
  File "/home/ubuntu/test2/Today.py", line 82, in date_keyword_search
    date_data = data[data['Date'].between(start_date, end_date)]
  File "/home/ubuntu/.local/lib/python3.9/site-packages/pandas/core/series.py", line 5485, in between
    lmask = self >= left
  File "/home/ubuntu/.local/lib/python3.9/site-packages/pandas/core/ops/common.py", line 81, in new_method
    return method(self, other)
  File "/home/ubuntu/.local/lib/python3.9/site-packages/pandas/core/arraylike.py", line 60, in __ge__
    return self._cmp_method(other, operator.ge)
  File "/home/ubuntu/.local/lib/python3.9/site-packages/pandas/core/series.py", line 6096, in _cmp_method
    res_values = ops.comparison_op(lvalues, rvalues, op)
  File "/home/ubuntu/.local/lib/python3.9/site-packages/pandas/core/ops/array_ops.py", line 279, in comparison_op
    res_values = op(lvalues, rvalues)
  File "/home/ubuntu/.local/lib/python3.9/site-packages/pandas/core/ops/common.py", line 81, in new_method
    return method(self, other)
  File "/home/ubuntu/.local/lib/python3.9/site-packages/pandas/core/arraylike.py", line 60, in __ge__
    return self._cmp_method(other, operator.ge)
  File "/home/ubuntu/.local/lib/python3.9/site-packages/pandas/core/arrays/datetimelike.py", line 937, in _cmp_method
    return invalid_comparison(self, other, op)
  File "/home/ubuntu/.local/lib/python3.9/site-packages/pandas/core/ops/invalid.py", line 36, in invalid_comparison
    raise TypeError(f"Invalid comparison between dtype={left.dtype} and {typ}")
TypeError: Invalid comparison between dtype=datetime64[ns] and int
2023-08-08 23:28:38.082 Uncaught app exception
Traceback (most recent call last):
  File "/home/ubuntu/.local/lib/python3.9/site-packages/pandas/core/arrays/datetimelike.py", line 935, in _cmp_method
    other = self._validate_comparison_value(other)
  File "/home/ubuntu/.local/lib/python3.9/site-packages/pandas/core/arrays/datetimelike.py", line 571, in _validate_comparison_value
    raise InvalidComparison(other)
pandas.errors.InvalidComparison: 20230808

During handling of the above exception, another exception occurred:

Traceback (most recent call last):
  File "/home/ubuntu/.local/lib/python3.9/site-packages/streamlit/runtime/scriptrunner/script_runner.py", line 552, in _run_script
    exec(code, module.__dict__)
  File "/home/ubuntu/test2/Today.py", line 132, in <module>
    president_number, president = date_keyword_search("대통령비서실", today, today)
  File "/home/ubuntu/test2/Today.py", line 82, in date_keyword_search
    date_data = data[data['Date'].between(start_date, end_date)]
  File "/home/ubuntu/.local/lib/python3.9/site-packages/pandas/core/series.py", line 5485, in between
    lmask = self >= left
  File "/home/ubuntu/.local/lib/python3.9/site-packages/pandas/core/ops/common.py", line 81, in new_method
    return method(self, other)
  File "/home/ubuntu/.local/lib/python3.9/site-packages/pandas/core/arraylike.py", line 60, in __ge__
    return self._cmp_method(other, operator.ge)
  File "/home/ubuntu/.local/lib/python3.9/site-packages/pandas/core/series.py", line 6096, in _cmp_method
    res_values = ops.comparison_op(lvalues, rvalues, op)
  File "/home/ubuntu/.local/lib/python3.9/site-packages/pandas/core/ops/array_ops.py", line 279, in comparison_op
    res_values = op(lvalues, rvalues)
  File "/home/ubuntu/.local/lib/python3.9/site-packages/pandas/core/ops/common.py", line 81, in new_method
    return method(self, other)
  File "/home/ubuntu/.local/lib/python3.9/site-packages/pandas/core/arraylike.py", line 60, in __ge__
    return self._cmp_method(other, operator.ge)
  File "/home/ubuntu/.local/lib/python3.9/site-packages/pandas/core/arrays/datetimelike.py", line 937, in _cmp_method
    return invalid_comparison(self, other, op)
  File "/home/ubuntu/.local/lib/python3.9/site-packages/pandas/core/ops/invalid.py", line 36, in invalid_comparison
    raise TypeError(f"Invalid comparison between dtype={left.dtype} and {typ}")
TypeError: Invalid comparison between dtype=datetime64[ns] and int
2023-08-08 23:30:41.870 Uncaught app exception
Traceback (most recent call last):
  File "/home/ubuntu/.local/lib/python3.9/site-packages/pandas/core/arrays/datetimelike.py", line 935, in _cmp_method
    other = self._validate_comparison_value(other)
  File "/home/ubuntu/.local/lib/python3.9/site-packages/pandas/core/arrays/datetimelike.py", line 571, in _validate_comparison_value
    raise InvalidComparison(other)
pandas.errors.InvalidComparison: 20230808

During handling of the above exception, another exception occurred:

Traceback (most recent call last):
  File "/home/ubuntu/.local/lib/python3.9/site-packages/streamlit/runtime/scriptrunner/script_runner.py", line 552, in _run_script
    exec(code, module.__dict__)
  File "/home/ubuntu/test2/Today.py", line 132, in <module>
    president_number, president = date_keyword_search("대통령비서실", today, today)
  File "/home/ubuntu/test2/Today.py", line 82, in date_keyword_search
    date_data = data[data['Date'].between(start_date, end_date)]
  File "/home/ubuntu/.local/lib/python3.9/site-packages/pandas/core/series.py", line 5485, in between
    lmask = self >= left
  File "/home/ubuntu/.local/lib/python3.9/site-packages/pandas/core/ops/common.py", line 81, in new_method
    return method(self, other)
  File "/home/ubuntu/.local/lib/python3.9/site-packages/pandas/core/arraylike.py", line 60, in __ge__
    return self._cmp_method(other, operator.ge)
  File "/home/ubuntu/.local/lib/python3.9/site-packages/pandas/core/series.py", line 6096, in _cmp_method
    res_values = ops.comparison_op(lvalues, rvalues, op)
  File "/home/ubuntu/.local/lib/python3.9/site-packages/pandas/core/ops/array_ops.py", line 279, in comparison_op
    res_values = op(lvalues, rvalues)
  File "/home/ubuntu/.local/lib/python3.9/site-packages/pandas/core/ops/common.py", line 81, in new_method
    return method(self, other)
  File "/home/ubuntu/.local/lib/python3.9/site-packages/pandas/core/arraylike.py", line 60, in __ge__
    return self._cmp_method(other, operator.ge)
  File "/home/ubuntu/.local/lib/python3.9/site-packages/pandas/core/arrays/datetimelike.py", line 937, in _cmp_method
    return invalid_comparison(self, other, op)
  File "/home/ubuntu/.local/lib/python3.9/site-packages/pandas/core/ops/invalid.py", line 36, in invalid_comparison
    raise TypeError(f"Invalid comparison between dtype={left.dtype} and {typ}")
TypeError: Invalid comparison between dtype=datetime64[ns] and int
2023-08-08 23:31:13.701 Uncaught app exception
Traceback (most recent call last):
  File "/home/ubuntu/.local/lib/python3.9/site-packages/pandas/core/arrays/datetimelike.py", line 935, in _cmp_method
    other = self._validate_comparison_value(other)
  File "/home/ubuntu/.local/lib/python3.9/site-packages/pandas/core/arrays/datetimelike.py", line 571, in _validate_comparison_value
    raise InvalidComparison(other)
pandas.errors.InvalidComparison: 20230808

During handling of the above exception, another exception occurred:

Traceback (most recent call last):
  File "/home/ubuntu/.local/lib/python3.9/site-packages/streamlit/runtime/scriptrunner/script_runner.py", line 552, in _run_script
    exec(code, module.__dict__)
  File "/home/ubuntu/test2/Today.py", line 132, in <module>
    president_number, president = date_keyword_search("대통령비서실", today, today)
  File "/home/ubuntu/test2/Today.py", line 82, in date_keyword_search
    date_data = data[data['Date'].between(start_date, end_date)]
  File "/home/ubuntu/.local/lib/python3.9/site-packages/pandas/core/series.py", line 5485, in between
    lmask = self >= left
  File "/home/ubuntu/.local/lib/python3.9/site-packages/pandas/core/ops/common.py", line 81, in new_method
    return method(self, other)
  File "/home/ubuntu/.local/lib/python3.9/site-packages/pandas/core/arraylike.py", line 60, in __ge__
    return self._cmp_method(other, operator.ge)
  File "/home/ubuntu/.local/lib/python3.9/site-packages/pandas/core/series.py", line 6096, in _cmp_method
    res_values = ops.comparison_op(lvalues, rvalues, op)
  File "/home/ubuntu/.local/lib/python3.9/site-packages/pandas/core/ops/array_ops.py", line 279, in comparison_op
    res_values = op(lvalues, rvalues)
  File "/home/ubuntu/.local/lib/python3.9/site-packages/pandas/core/ops/common.py", line 81, in new_method
    return method(self, other)
  File "/home/ubuntu/.local/lib/python3.9/site-packages/pandas/core/arraylike.py", line 60, in __ge__
    return self._cmp_method(other, operator.ge)
  File "/home/ubuntu/.local/lib/python3.9/site-packages/pandas/core/arrays/datetimelike.py", line 937, in _cmp_method
    return invalid_comparison(self, other, op)
  File "/home/ubuntu/.local/lib/python3.9/site-packages/pandas/core/ops/invalid.py", line 36, in invalid_comparison
    raise TypeError(f"Invalid comparison between dtype={left.dtype} and {typ}")
TypeError: Invalid comparison between dtype=datetime64[ns] and int
2023-08-08 23:31:20.053 Uncaught app exception
Traceback (most recent call last):
  File "/home/ubuntu/.local/lib/python3.9/site-packages/pandas/core/arrays/datetimelike.py", line 935, in _cmp_method
    other = self._validate_comparison_value(other)
  File "/home/ubuntu/.local/lib/python3.9/site-packages/pandas/core/arrays/datetimelike.py", line 571, in _validate_comparison_value
    raise InvalidComparison(other)
pandas.errors.InvalidComparison: 20230808

During handling of the above exception, another exception occurred:

Traceback (most recent call last):
  File "/home/ubuntu/.local/lib/python3.9/site-packages/streamlit/runtime/scriptrunner/script_runner.py", line 552, in _run_script
    exec(code, module.__dict__)
  File "/home/ubuntu/test2/Today.py", line 132, in <module>
    president_number, president = date_keyword_search("대통령비서실", today, today)
  File "/home/ubuntu/test2/Today.py", line 82, in date_keyword_search
    date_data = data[data['Date'].between(start_date, end_date)]
  File "/home/ubuntu/.local/lib/python3.9/site-packages/pandas/core/series.py", line 5485, in between
    lmask = self >= left
  File "/home/ubuntu/.local/lib/python3.9/site-packages/pandas/core/ops/common.py", line 81, in new_method
    return method(self, other)
  File "/home/ubuntu/.local/lib/python3.9/site-packages/pandas/core/arraylike.py", line 60, in __ge__
    return self._cmp_method(other, operator.ge)
  File "/home/ubuntu/.local/lib/python3.9/site-packages/pandas/core/series.py", line 6096, in _cmp_method
    res_values = ops.comparison_op(lvalues, rvalues, op)
  File "/home/ubuntu/.local/lib/python3.9/site-packages/pandas/core/ops/array_ops.py", line 279, in comparison_op
    res_values = op(lvalues, rvalues)
  File "/home/ubuntu/.local/lib/python3.9/site-packages/pandas/core/ops/common.py", line 81, in new_method
    return method(self, other)
  File "/home/ubuntu/.local/lib/python3.9/site-packages/pandas/core/arraylike.py", line 60, in __ge__
    return self._cmp_method(other, operator.ge)
  File "/home/ubuntu/.local/lib/python3.9/site-packages/pandas/core/arrays/datetimelike.py", line 937, in _cmp_method
    return invalid_comparison(self, other, op)
  File "/home/ubuntu/.local/lib/python3.9/site-packages/pandas/core/ops/invalid.py", line 36, in invalid_comparison
    raise TypeError(f"Invalid comparison between dtype={left.dtype} and {typ}")
TypeError: Invalid comparison between dtype=datetime64[ns] and int
2023-08-08 23:32:06.570 Uncaught app exception
Traceback (most recent call last):
  File "/home/ubuntu/.local/lib/python3.9/site-packages/pandas/core/arrays/datetimelike.py", line 935, in _cmp_method
    other = self._validate_comparison_value(other)
  File "/home/ubuntu/.local/lib/python3.9/site-packages/pandas/core/arrays/datetimelike.py", line 571, in _validate_comparison_value
    raise InvalidComparison(other)
pandas.errors.InvalidComparison: 20230808

During handling of the above exception, another exception occurred:

Traceback (most recent call last):
  File "/home/ubuntu/.local/lib/python3.9/site-packages/streamlit/runtime/scriptrunner/script_runner.py", line 552, in _run_script
    exec(code, module.__dict__)
  File "/home/ubuntu/test2/Today.py", line 132, in <module>
    president_number, president = date_keyword_search("대통령비서실", today, today)
  File "/home/ubuntu/test2/Today.py", line 82, in date_keyword_search
    date_data = data[data['Date'].between(start_date, end_date)]
  File "/home/ubuntu/.local/lib/python3.9/site-packages/pandas/core/series.py", line 5485, in between
    lmask = self >= left
  File "/home/ubuntu/.local/lib/python3.9/site-packages/pandas/core/ops/common.py", line 81, in new_method
    return method(self, other)
  File "/home/ubuntu/.local/lib/python3.9/site-packages/pandas/core/arraylike.py", line 60, in __ge__
    return self._cmp_method(other, operator.ge)
  File "/home/ubuntu/.local/lib/python3.9/site-packages/pandas/core/series.py", line 6096, in _cmp_method
    res_values = ops.comparison_op(lvalues, rvalues, op)
  File "/home/ubuntu/.local/lib/python3.9/site-packages/pandas/core/ops/array_ops.py", line 279, in comparison_op
    res_values = op(lvalues, rvalues)
  File "/home/ubuntu/.local/lib/python3.9/site-packages/pandas/core/ops/common.py", line 81, in new_method
    return method(self, other)
  File "/home/ubuntu/.local/lib/python3.9/site-packages/pandas/core/arraylike.py", line 60, in __ge__
    return self._cmp_method(other, operator.ge)
  File "/home/ubuntu/.local/lib/python3.9/site-packages/pandas/core/arrays/datetimelike.py", line 937, in _cmp_method
    return invalid_comparison(self, other, op)
  File "/home/ubuntu/.local/lib/python3.9/site-packages/pandas/core/ops/invalid.py", line 36, in invalid_comparison
    raise TypeError(f"Invalid comparison between dtype={left.dtype} and {typ}")
TypeError: Invalid comparison between dtype=datetime64[ns] and int
2023-08-08 23:32:14.610 Uncaught app exception
Traceback (most recent call last):
  File "/home/ubuntu/.local/lib/python3.9/site-packages/pandas/core/arrays/datetimelike.py", line 935, in _cmp_method
    other = self._validate_comparison_value(other)
  File "/home/ubuntu/.local/lib/python3.9/site-packages/pandas/core/arrays/datetimelike.py", line 571, in _validate_comparison_value
    raise InvalidComparison(other)
pandas.errors.InvalidComparison: 20230808

During handling of the above exception, another exception occurred:

Traceback (most recent call last):
  File "/home/ubuntu/.local/lib/python3.9/site-packages/streamlit/runtime/scriptrunner/script_runner.py", line 552, in _run_script
    exec(code, module.__dict__)
  File "/home/ubuntu/test2/Today.py", line 132, in <module>
    president_number, president = date_keyword_search("대통령비서실", today, today)
  File "/home/ubuntu/test2/Today.py", line 82, in date_keyword_search
    date_data = data[data['Date'].between(start_date, end_date)]
  File "/home/ubuntu/.local/lib/python3.9/site-packages/pandas/core/series.py", line 5485, in between
    lmask = self >= left
  File "/home/ubuntu/.local/lib/python3.9/site-packages/pandas/core/ops/common.py", line 81, in new_method
    return method(self, other)
  File "/home/ubuntu/.local/lib/python3.9/site-packages/pandas/core/arraylike.py", line 60, in __ge__
    return self._cmp_method(other, operator.ge)
  File "/home/ubuntu/.local/lib/python3.9/site-packages/pandas/core/series.py", line 6096, in _cmp_method
    res_values = ops.comparison_op(lvalues, rvalues, op)
  File "/home/ubuntu/.local/lib/python3.9/site-packages/pandas/core/ops/array_ops.py", line 279, in comparison_op
    res_values = op(lvalues, rvalues)
  File "/home/ubuntu/.local/lib/python3.9/site-packages/pandas/core/ops/common.py", line 81, in new_method
    return method(self, other)
  File "/home/ubuntu/.local/lib/python3.9/site-packages/pandas/core/arraylike.py", line 60, in __ge__
    return self._cmp_method(other, operator.ge)
  File "/home/ubuntu/.local/lib/python3.9/site-packages/pandas/core/arrays/datetimelike.py", line 937, in _cmp_method
    return invalid_comparison(self, other, op)
  File "/home/ubuntu/.local/lib/python3.9/site-packages/pandas/core/ops/invalid.py", line 36, in invalid_comparison
    raise TypeError(f"Invalid comparison between dtype={left.dtype} and {typ}")
TypeError: Invalid comparison between dtype=datetime64[ns] and int
2023-08-08 23:37:51.267 Uncaught app exception
Traceback (most recent call last):
  File "/home/ubuntu/.local/lib/python3.9/site-packages/streamlit/runtime/scriptrunner/script_runner.py", line 552, in _run_script
    exec(code, module.__dict__)
  File "/home/ubuntu/test2/Today.py", line 126, in <module>
    today = re.sub('-', '', today)
  File "/usr/lib/python3.9/re.py", line 210, in sub
    return _compile(pattern, flags).sub(repl, string, count)
TypeError: expected string or bytes-like object
2023-08-08 23:38:37.340 Uncaught app exception
Traceback (most recent call last):
  File "/home/ubuntu/.local/lib/python3.9/site-packages/streamlit/runtime/scriptrunner/script_runner.py", line 552, in _run_script
    exec(code, module.__dict__)
  File "/home/ubuntu/test2/Today.py", line 127, in <module>
    today = re.sub('-', '', today)
  File "/usr/lib/python3.9/re.py", line 210, in sub
    return _compile(pattern, flags).sub(repl, string, count)
TypeError: expected string or bytes-like object
2023-08-08 23:38:50.766 Uncaught app exception
Traceback (most recent call last):
  File "/home/ubuntu/.local/lib/python3.9/site-packages/streamlit/runtime/scriptrunner/script_runner.py", line 552, in _run_script
    exec(code, module.__dict__)
  File "/home/ubuntu/test2/Today.py", line 204, in <module>
    st.text(message)
NameError: name 'message' is not defined
2023-08-08 23:39:12.035 Uncaught app exception
Traceback (most recent call last):
  File "/home/ubuntu/.local/lib/python3.9/site-packages/streamlit/runtime/scriptrunner/script_runner.py", line 552, in _run_script
    exec(code, module.__dict__)
  File "/home/ubuntu/test2/Today.py", line 205, in <module>
    st.text(message)
NameError: name 'message' is not defined
2023-08-08 23:39:32.643 Uncaught app exception
Traceback (most recent call last):
  File "/home/ubuntu/.local/lib/python3.9/site-packages/streamlit/runtime/scriptrunner/script_runner.py", line 552, in _run_script
    exec(code, module.__dict__)
  File "/home/ubuntu/test2/Today.py", line 205, in <module>
    st.text(message)
NameError: name 'message' is not defined
2023-08-08 23:40:56.533 Uncaught app exception
Traceback (most recent call last):
  File "/home/ubuntu/.local/lib/python3.9/site-packages/streamlit/runtime/scriptrunner/script_runner.py", line 552, in _run_script
    exec(code, module.__dict__)
  File "/home/ubuntu/test2/Today.py", line 205, in <module>
    st.subheader(f"{today} 주요 보도")
NameError: name 'message' is not defined
2023-08-08 23:41:35.239 Uncaught app exception
Traceback (most recent call last):
  File "/home/ubuntu/.local/lib/python3.9/site-packages/streamlit/runtime/scriptrunner/script_runner.py", line 552, in _run_script
    exec(code, module.__dict__)
  File "/home/ubuntu/test2/Today.py", line 205, in <module>
    with st.container():
NameError: name 'message' is not defined
2023-08-08 23:42:13.005 Uncaught app exception
Traceback (most recent call last):
  File "/home/ubuntu/.local/lib/python3.9/site-packages/streamlit/runtime/scriptrunner/script_runner.py", line 552, in _run_script
    exec(code, module.__dict__)
  File "/home/ubuntu/test2/Today.py", line 205, in <module>
    with st.container():
NameError: name 'message' is not defined
2023-08-08 23:42:38.386 Uncaught app exception
Traceback (most recent call last):
  File "/home/ubuntu/.local/lib/python3.9/site-packages/streamlit/runtime/scriptrunner/script_runner.py", line 552, in _run_script
    exec(code, module.__dict__)
  File "/home/ubuntu/test2/Today.py", line 205, in <module>
    with st.container():
NameError: name 'message' is not defined
2023-08-08 23:42:44.035 Uncaught app exception
Traceback (most recent call last):
  File "/home/ubuntu/.local/lib/python3.9/site-packages/streamlit/runtime/scriptrunner/script_runner.py", line 552, in _run_script
    exec(code, module.__dict__)
  File "/home/ubuntu/test2/Today.py", line 205, in <module>
    with st.container():
NameError: name 'message' is not defined
2023-08-08 23:42:52.533 Uncaught app exception
Traceback (most recent call last):
  File "/home/ubuntu/.local/lib/python3.9/site-packages/streamlit/runtime/scriptrunner/script_runner.py", line 552, in _run_script
    exec(code, module.__dict__)
  File "/home/ubuntu/test2/Today.py", line 205, in <module>
    with st.container():
NameError: name 'message' is not defined
2023-08-08 23:43:58.150 Uncaught app exception
Traceback (most recent call last):
  File "/home/ubuntu/.local/lib/python3.9/site-packages/streamlit/runtime/scriptrunner/script_runner.py", line 552, in _run_script
    exec(code, module.__dict__)
  File "/home/ubuntu/test2/Today.py", line 205, in <module>
    with st.container():
NameError: name 'message' is not defined
2023-08-08 23:44:02.705 Uncaught app exception
Traceback (most recent call last):
  File "/home/ubuntu/.local/lib/python3.9/site-packages/streamlit/runtime/scriptrunner/script_runner.py", line 552, in _run_script
    exec(code, module.__dict__)
  File "/home/ubuntu/test2/Today.py", line 205, in <module>
    with st.container():
NameError: name 'message' is not defined
2023-08-08 23:44:05.854 Uncaught app exception
Traceback (most recent call last):
  File "/home/ubuntu/.local/lib/python3.9/site-packages/streamlit/runtime/scriptrunner/script_runner.py", line 552, in _run_script
    exec(code, module.__dict__)
  File "/home/ubuntu/test2/Today.py", line 205, in <module>
    with st.container():
NameError: name 'message' is not defined
2023-08-08 23:44:27.022 Uncaught app exception
Traceback (most recent call last):
  File "/home/ubuntu/.local/lib/python3.9/site-packages/streamlit/runtime/scriptrunner/script_runner.py", line 552, in _run_script
    exec(code, module.__dict__)
  File "/home/ubuntu/test2/Today.py", line 205, in <module>
    with st.container():
NameError: name 'message' is not defined
2023-08-08
2023-08-08
2023-08-08
2023-08-08 00:00:00
2023-08-08
2023-08-08 00:00:00
2023-08-08
2023-08-08 00:00:00
2023-08-08
2023-08-08 00:00:00
2023-08-08
2023-08-08 00:00:00
2023-08-08
2023-08-08 00:00:00
2023-08-08
2023-08-08 00:00:00
2023-08-08
2023-08-08 00:00:00
2023-08-08
2023-08-08 00:00:00
2023-08-08
2023-08-08 00:00:00
2023-08-08
2023-08-08 00:00:00
2023-08-08
2023-08-08 00:00:00
  Stopping...

Collecting usage statistics. To deactivate, set browser.gatherUsageStats to False.


  You can now view your Streamlit app in your browser.

  Network URL: http://172.31.37.193:8501
  External URL: http://3.37.158.200:8501

using cached model. /home/ubuntu/test2/.cache/kobert_v1.zip
using cached model. /home/ubuntu/test2/.cache/kobert_news_wiki_ko_cased-1087f8699e.spiece
using cached model. /home/ubuntu/test2/.cache/kobert_news_wiki_ko_cased-1087f8699e.spiece
using cached model. /home/ubuntu/test2/.cache/kobert_v1.zip
using cached model. /home/ubuntu/test2/.cache/kobert_news_wiki_ko_cased-1087f8699e.spiece
using cached model. /home/ubuntu/test2/.cache/kobert_news_wiki_ko_cased-1087f8699e.spiece
  Stopping...

Collecting usage statistics. To deactivate, set browser.gatherUsageStats to False.


  You can now view your Streamlit app in your browser.

  Network URL: http://172.31.37.193:8501
  External URL: http://3.37.158.200:8501

2023-08-09 12:43:44.416 Uncaught app exception
Traceback (most recent call last):
  File "/home/ubuntu/.local/lib/python3.9/site-packages/streamlit/runtime/scriptrunner/script_runner.py", line 552, in _run_script
    exec(code, module.__dict__)
  File "/home/ubuntu/test2/pages/Keyword Analysis.py", line 225, in <module>
    wc.generate_from_frequencies(top_related_words)
  File "/home/ubuntu/.local/lib/python3.9/site-packages/wordcloud/wordcloud.py", line 410, in generate_from_frequencies
    raise ValueError("We need at least 1 word to plot a word cloud, "
ValueError: We need at least 1 word to plot a word cloud, got 0.
2023-08-09 12:45:08.934 Uncaught app exception
Traceback (most recent call last):
  File "/home/ubuntu/.local/lib/python3.9/site-packages/streamlit/runtime/scriptrunner/script_runner.py", line 552, in _run_script
    exec(code, module.__dict__)
  File "/home/ubuntu/test2/pages/Keyword Analysis.py", line 173, in <module>
    date_top_related_words.iloc[d,0] = f'{date_top_related_words.iloc[d,0]}  :  {date_top_related_words.iloc[d,1]}건'
  File "/home/ubuntu/.local/lib/python3.9/site-packages/pandas/core/indexing.py", line 1096, in __getitem__
    return self.obj._get_value(*key, takeable=self._takeable)
  File "/home/ubuntu/.local/lib/python3.9/site-packages/pandas/core/frame.py", line 3868, in _get_value
    return series._values[index]
IndexError: index 5 is out of bounds for axis 0 with size 5
2023-08-09 12:45:47.875 Uncaught app exception
Traceback (most recent call last):
  File "/home/ubuntu/.local/lib/python3.9/site-packages/streamlit/runtime/scriptrunner/script_runner.py", line 552, in _run_script
    exec(code, module.__dict__)
  File "/home/ubuntu/test2/pages/Keyword Analysis.py", line 173, in <module>
    date_top_related_words.iloc[d,0] = f'{date_top_related_words.iloc[d,0]}  :  {date_top_related_words.iloc[d,1]}건'
  File "/home/ubuntu/.local/lib/python3.9/site-packages/pandas/core/indexing.py", line 1096, in __getitem__
    return self.obj._get_value(*key, takeable=self._takeable)
  File "/home/ubuntu/.local/lib/python3.9/site-packages/pandas/core/frame.py", line 3868, in _get_value
    return series._values[index]
IndexError: index 12 is out of bounds for axis 0 with size 12
2023-08-09 12:46:01.392 Uncaught app exception
Traceback (most recent call last):
  File "/home/ubuntu/.local/lib/python3.9/site-packages/streamlit/runtime/scriptrunner/script_runner.py", line 552, in _run_script
    exec(code, module.__dict__)
  File "/home/ubuntu/test2/pages/Keyword Analysis.py", line 173, in <module>
    date_top_related_words.iloc[d,0] = f'{date_top_related_words.iloc[d,0]}  :  {date_top_related_words.iloc[d,1]}건'
  File "/home/ubuntu/.local/lib/python3.9/site-packages/pandas/core/indexing.py", line 1096, in __getitem__
    return self.obj._get_value(*key, takeable=self._takeable)
  File "/home/ubuntu/.local/lib/python3.9/site-packages/pandas/core/frame.py", line 3868, in _get_value
    return series._values[index]
IndexError: index 5 is out of bounds for axis 0 with size 5
2023-08-09 12:46:42.105 Uncaught app exception
Traceback (most recent call last):
  File "/home/ubuntu/.local/lib/python3.9/site-packages/transformers/modeling_utils.py", line 1211, in from_pretrained
    state_dict = torch.load(resolved_archive_file, map_location="cpu")
  File "/home/ubuntu/.local/lib/python3.9/site-packages/torch/serialization.py", line 608, in load
    return _legacy_load(opened_file, map_location, pickle_module, **pickle_load_args)
  File "/home/ubuntu/.local/lib/python3.9/site-packages/torch/serialization.py", line 794, in _legacy_load
    deserialized_objects[key]._set_from_file(f, offset, f_should_read_directly)
RuntimeError: unexpected EOF, expected 8 more bytes. The file might be corrupted.

During handling of the above exception, another exception occurred:

Traceback (most recent call last):
  File "/home/ubuntu/.local/lib/python3.9/site-packages/streamlit/runtime/scriptrunner/script_runner.py", line 552, in _run_script
    exec(code, module.__dict__)
  File "/home/ubuntu/test2/pages/Keyword Analysis.py", line 276, in <module>
    bertmodel, vocab = get_pytorch_kobert_model()
  File "/home/ubuntu/.local/lib/python3.9/site-packages/kobert/pytorch_kobert.py", line 52, in get_pytorch_kobert_model
    return get_kobert_model(model_path, vocab_path, ctx)
  File "/home/ubuntu/.local/lib/python3.9/site-packages/kobert/pytorch_kobert.py", line 27, in get_kobert_model
    bertmodel = BertModel.from_pretrained(model_path, return_dict=False)
  File "/home/ubuntu/.local/lib/python3.9/site-packages/transformers/modeling_utils.py", line 1213, in from_pretrained
    raise OSError(
OSError: Unable to load weights from pytorch checkpoint file for '.cache/kobert_from_pretrained' at '.cache/kobert_from_pretrained/pytorch_model.bin'If you tried to load a PyTorch model from a TF 2.0 checkpoint, please set from_tf=True. 
2023-08-10 08:50:53.024 Uncaught app exception
Traceback (most recent call last):
  File "/home/ubuntu/.local/lib/python3.9/site-packages/streamlit/runtime/scriptrunner/script_runner.py", line 552, in _run_script
    exec(code, module.__dict__)
  File "/home/ubuntu/test2/pages/Keyword Analysis.py", line 225, in <module>
    wc.generate_from_frequencies(top_related_words)
  File "/home/ubuntu/.local/lib/python3.9/site-packages/wordcloud/wordcloud.py", line 410, in generate_from_frequencies
    raise ValueError("We need at least 1 word to plot a word cloud, "
ValueError: We need at least 1 word to plot a word cloud, got 0.
